{"id": 1, "eval_result": [{"cause_line_score": 1, "effect_line_score": 1, "error_type_score": 0, "error_message_score": 0.0, "error_message_eval_reason": "The error message described in the LLM Output ('too many values to unpack (expected 2)') is completely different from the Ground Truth ('X must have 2 or fewer dimensions'). The error type in the LLM Output does not match the Ground Truth, and the described issue is irrelevant to the actual error."}, {"cause_line_score": 1, "effect_line_score": 1, "error_type_score": 0, "error_message_score": 0.5, "error_message_eval_reason": "The LLM described that error related to 'whis' must be a scalar or a length-2 sequence, which is somewhat related but incorrect because the Ground Truth specifies the error as 'not enough values to unpack (expected 2, got 1)', indicating a problem with unpacking values, not specifically the type of 'whis'. The message is partially correct but deviates in the details."}, {"cause_line_score": 1, "effect_line_score": 1, "error_type_score": 0, "error_message_score": 0.0, "error_message_eval_reason": "The error description in the LLM Output is completely incorrect. The Ground Truth error message is a TypeError related to multiplying a sequence by a non-int of type 'numpy.float64', while the LLM Output incorrectly identifies the error as a ValueError related to 'dpi' having to be an integer or float."}, {"cause_line_score": 1, "effect_line_score": 1, "error_type_score": 1, "error_message_score": 0.75, "error_message_eval_reason": "The error message in the LLM Output matches the Ground Truth in identifying the unexpected keyword argument 'outliersize', but the LLM Output uses 'boxplot()' instead of 'Axes.boxplot()'. The difference is minor, but relevant for exact matching."}, {"cause_line_score": 0, "effect_line_score": 0, "error_type_score": 0, "error_message_score": 0.0, "error_message_eval_reason": "The error message in the LLM Output ('ValueError: list index out of range') is completely irrelevant to the GT error message ('ValueError: whis must be a float or list of percentiles'). The error types do not match, and the cause and effect lines also do not align with the ground truth."}, {"cause_line_score": 0, "effect_line_score": 0, "error_type_score": 0, "error_message_score": 0.0, "error_message_eval_reason": "The LLM's output cause line and effect line are completely different from the ground truth ones. The ground truth error relates to an incorrect value for the 'whis' parameter in the 'boxplot' method, while the LLM's output refers to a nonexistent attribute 'patches' for an 'AxesSubplot' object. Consequently, the error messages are entirely different."}, {"cause_line_score": 0, "effect_line_score": 0, "error_type_score": 0, "error_message_score": 0.0, "error_message_eval_reason": "The error message in the LLM output ('TypeError: boxplot() got an unexpected keyword argument 'patch_artist'') is completely different from the error message in the Ground Truth ('ValueError: whis must be a float or list of percentiles'). The error types and messages do not match in any aspect."}]}
{"id": 2, "eval_result": [{"cause_line_score": 0, "effect_line_score": 1, "error_type_score": 1, "error_message_score": 0.75, "error_message_eval_reason": "The LLM Output error message 'x and y must have same length' is a slightly simplified but mostly correct version of the Ground Truth error message 'x and y must have the same first dimension, but have shapes (50,) and (400,)'. The key detail of mismatched dimensions is conveyed, but the specific shapes (50,) and (400,) are omitted."}, {"cause_line_score": 0, "effect_line_score": 0, "error_type_score": 0, "error_message_score": 0.0, "error_message_eval_reason": "The LLM's error message 'module' object has no attribute 'Series' is not related to the actual error message 'NameError: name 'pd' is not defined. Did you mean: 'id'?'. The provided error description is completely irrelevant to the ground truth."}, {"cause_line_score": 0, "effect_line_score": 0, "error_type_score": 1, "error_message_score": 0.75, "error_message_eval_reason": "The error description is mostly correct and captures the primary issue of 'matplotplot' not being a defined name, but it lacks the suggestion to use 'matplotlib'."}, {"cause_line_score": 1, "effect_line_score": 1, "error_type_score": 1, "error_message_score": 1.0, "error_message_eval_reason": "The error message in the LLM Output 'KeyError: \"'-z**3 against w + 2'\"' exactly matches the error message in the Ground Truth 'KeyError: '-z**3 against w + 2''. Therefore, it is a complete match with all key details included."}]}
{"id": 3, "eval_result": [{"cause_line_score": 1, "effect_line_score": 1, "error_type_score": 0, "error_message_score": 0.0, "error_message_eval_reason": "The LLM output provides an 'AttributeError' whereas the GT indicates a 'NameError' due to 'pd' not being defined. The error descriptions are completely different, leading to a score of 0.0."}, {"cause_line_score": 0, "effect_line_score": 0, "error_type_score": 0, "error_message_score": 0.0, "error_message_eval_reason": "The error description 'TypeError: 'NoneType' object is not subscriptable' in the LLM output is completely different from the ground truth error description 'ValueError: zero-size array to reduction operation minimum which has no identity'. Hence, the LLM output is entirely incorrect, and the error description is completely irrelevant to the GT."}, {"cause_line_score": 1, "effect_line_score": 1, "error_type_score": 0, "error_message_score": 0.0, "error_message_eval_reason": "The LLM's error description is completely irrelevant to the Ground Truth error message. The Ground Truth error is about a missing 'pd' import (NameError), while the LLM's error message identifies a non-existent attribute (AttributeError)."}, {"cause_line_score": 0, "effect_line_score": 0, "error_type_score": 0, "error_message_score": 0.0, "error_message_eval_reason": "The error description in the LLM Output 'ValueError: not enough values to unpack (expected 3, got 2)' is completely different from the Ground Truth 'AttributeError: 'Axes' object has no attribute 'set_edgecolor'. Did you mean: 'set_facecolor'?'."}, {"cause_line_score": 0, "effect_line_score": 0, "error_type_score": 0, "error_message_score": 0.0, "error_message_eval_reason": "The LLM Output's error message ('AxesSubplot' object has no attribute 'violinplot') refers to an unrelated issue compared to the Ground Truth ('TypeError: 'other' must be an instance of matplotlib.axes._base._AxesBase, not a bool'). The cause and effect lines in the LLM Output also refer to different lines of code and errors that do not match those in the Ground Truth, resulting in scores of 0 for cause, effect, and error type."}, {"cause_line_score": 1, "effect_line_score": 1, "error_type_score": 0, "error_message_score": 0.0, "error_message_eval_reason": "The error message in the LLM output is 'AxesSubplot' object has no attribute 'violinplot', which is completely incorrect compared to the ground truth message that states 'TypeError: Axes.violinplot() got an unexpected keyword argument 'body''. The ground truth specifies a TypeError due to an unexpected keyword argument, while the LLM output suggests an AttributeError, leading to a completely incorrect analysis."}]}
{"id": 4, "eval_result": [{"cause_line_score": 1, "effect_line_score": 1, "error_type_score": 1, "error_message_score": 1.0, "error_message_eval_reason": "The error message 'AttributeError: 'list' object has no attribute 'dot'' in the LLM output exactly matches the error message in the Ground Truth, including all key details."}, {"cause_line_score": 0, "effect_line_score": 0, "error_type_score": 0, "error_message_score": 0.0, "error_message_eval_reason": "The error description provided by the LLM Output ('TypeError: 'tuple' object is not subscriptable') is completely irrelevant to the Ground Truth error ('TypeError: cannot unpack non-iterable Axes object'). The cause and effect lines also do not match, and the error types are different."}, {"cause_line_score": 0, "effect_line_score": 0, "error_type_score": 0, "error_message_score": 0.0, "error_message_eval_reason": "The LLM output provided a completely different kind of error that is unrelated to the ground truth. The cause, effect lines, and error messages differ significantly from those in the ground truth, and the error type (TypeError) does not match the ground truth's (NameError). The two sets of information are entirely unrelated."}, {"cause_line_score": 0, "effect_line_score": 0, "error_type_score": 0, "error_message_score": 0.0, "error_message_eval_reason": "The error message provided in the LLM Output, 'ValueError: x and y must have the same length,' is completely irrelevant to the Ground Truth error message, 'ValueError: RGBA sequence should have length 3 or 4.'"}, {"cause_line_score": 0, "effect_line_score": 0, "error_type_score": 0, "error_message_score": 0.0, "error_message_eval_reason": "The error message in the LLM Output ('ValueError: too many values to unpack (expected 1)') is completely irrelevant to the Ground Truth error message ('AttributeError: 'list' object has no attribute 'shape''). The error type is different, and the details of the error description do not match at all."}, {"cause_line_score": 0, "effect_line_score": 0, "error_type_score": 0, "error_message_score": 0.0, "error_message_eval_reason": "The cause_line, effect_line, and error_message provided by the LLM Output do not match those in the Ground Truth at all. The error message 'Ellipse' object has no attribute 'get_label' is completely irrelevant to the Ground Truth error message 'TypeError: only length-1 arrays can be converted to Python scalars'. Therefore, the cause_line_score, effect_line_score, error_type_score, and error_message_score are all 0."}]}
{"id": 5, "eval_result": [{"cause_line_score": 0, "effect_line_score": 0, "error_type_score": 0, "error_message_score": 0.25, "error_message_eval_reason": "The provided error message in the LLM Output has some relevance because it identifies a ValueError, which is the same type of error found in the Ground Truth. However, the specific error messages differ. The Ground Truth mentions a 'shape mismatch' while the LLM Output mentions 'too many indices for array'. Therefore, the LLM's error message is only loosely related to the actual error described in the Ground Truth."}, {"cause_line_score": 0, "effect_line_score": 0, "error_type_score": 0, "error_message_score": 0.0, "error_message_eval_reason": "The provided error message from the LLM Output ('IndexError: index 12 is out of bounds for axis 0 with size 20') is entirely different from the error message in the Ground Truth ('ValueError: shape mismatch: objects cannot be broadcast to a single shape.  Mismatch is between arg 0 with shape (6,) and arg 3 with shape (3,).'). This error message is not relevant to the Ground Truth error."}, {"cause_line_score": 0, "effect_line_score": 0, "error_type_score": 0, "error_message_score": 0.0, "error_message_eval_reason": "The error description in the LLM Output indicates a shape mismatch between different dimensions (3 and 2), whereas the GT indicates a mismatch between different objects with shapes (3,) and (2,). The details do not align correctly."}]}
{"id": 6, "eval_result": [{"cause_line_score": 0, "effect_line_score": 0, "error_type_score": 0, "error_message_score": 0.0, "error_message_eval_reason": "The error message provided by the LLM Output is entirely different from the Ground Truth. The Ground Truth error is a ValueError related to an invalid seed value for np.random.seed, whereas the LLM Output describes an AttributeError related to matplotlib having no attribute 'use'."}, {"cause_line_score": 1, "effect_line_score": 1, "error_type_score": 0, "error_message_score": 0.0, "error_message_eval_reason": "The LLM Output's error message 'ValueError: too many values to unpack (expected 2)' is completely irrelevant and does not match the Ground Truth error message 'ValueError: shape mismatch: objects cannot be broadcast to a single shape'."}, {"cause_line_score": 0, "effect_line_score": 0, "error_type_score": 0, "error_message_score": 0.0, "error_message_eval_reason": "The provided LLM output does not match the ground truth. The LLM has completely misidentified the cause and effect lines, as well as the error type. The ground truth error is a 'NameError' related to the undefined name 'pd', while the LLM output refers to a 'RuntimeError' related to matplotlib backend settings. These errors are entirely different in nature and context."}, {"cause_line_score": 0, "effect_line_score": 0, "error_type_score": 0, "error_message_score": 0.0, "error_message_eval_reason": "The LLM's error message, 'FileNotFoundError: [Errno 2] No such file or directory: 'data.csv'', is completely different from the Ground Truth error message, 'KeyError: 'diameter'. There is no overlap in the types of errors or their descriptions."}]}
{"id": 7, "eval_result": [{"cause_line_score": 1, "effect_line_score": 0, "error_type_score": 1, "error_message_score": 0.75, "error_message_eval_reason": "The error description in the LLM Output matches the Ground Truth except for the additional suggestion 'Did you mean: 'id'?' which is present in the Ground Truth but not in the LLM Output."}, {"cause_line_score": 1, "effect_line_score": 0, "error_type_score": 0, "error_message_score": 0.75, "error_message_eval_reason": "The LLM output correctly identifies the dimension mismatch as the error, which is the key detail. However, it does not provide as detailed an error message as the Ground Truth, missing the specific shapes involved (150 and 15)."}, {"cause_line_score": 0, "effect_line_score": 0, "error_type_score": 0, "error_message_score": 0.0, "error_message_eval_reason": "The LLM Output contains a completely different cause line, effect line, and error type than the Ground Truth. The Ground Truth indicates a ValueError related to an invalid linestyle, while the LLM Output indicates a length mismatch error for x_seq_2 and y_seq_sqrt, which is irrelevant to the provided Ground Truth error."}, {"cause_line_score": 1, "effect_line_score": 1, "error_type_score": 0, "error_message_score": 0.0, "error_message_eval_reason": "The error message in the LLM Output is completely incorrect. The ground truth error is related to an invalid value for the linestyle ('s-') in the plot function, while the LLM Output incorrectly identifies an issue with x and y having different lengths, which is unrelated to the actual error."}, {"cause_line_score": 1, "effect_line_score": 1, "error_type_score": 0, "error_message_score": 0.75, "error_message_eval_reason": "The error message provided by the LLM Output is mostly correct because it identifies 's-' as the issue related to the linestyle parameter. However, it inaccurately describes 's-' as an unrecognized marker style, while the actual error states that 's-' is not a valid value for the linestyle parameter."}, {"cause_line_score": 0, "effect_line_score": 0, "error_type_score": 0, "error_message_score": 0.0, "error_message_eval_reason": "The LLM Output suggests a different error ('AttributeError') than the Ground Truth ('ValueError'). Additionally, the lines pinpointed as cause and effect are not the same as those in the Ground Truth. The error message provided by the LLM Output is completely irrelevant to the Ground Truth error message."}]}
{"id": 8, "eval_result": [{"cause_line_score": 1, "effect_line_score": 1, "error_type_score": 1, "error_message_score": 1.0, "error_message_eval_reason": "The error message in the LLM Output exactly matches the Ground Truth, as both indicate a ValueError with the message: 'The truth value of an array with more than one element is ambiguous. Use a.any() or a.all()'."}, {"cause_line_score": 1, "effect_line_score": 1, "error_type_score": 0, "error_message_score": 0.0, "error_message_eval_reason": "The provided error message 'ValueError: setting an array element with a sequence.' is completely irrelevant to the actual error message which is 'TypeError: alpha must be numeric or None, not <class 'numpy.ndarray'>'."}, {"cause_line_score": 1, "effect_line_score": 1, "error_type_score": 0, "error_message_score": 0.0, "error_message_eval_reason": "The LLM output error message 'ValueError: setting an array element with a sequence' does not match the ground truth error message 'ValueError: Invalid RGBA argument: array('blue', dtype='<U6')'. This indicates that the LLM misunderstood the nature of the error, which is related to an invalid color format for the RGBA argument, not array element sequence issues."}]}
{"id": 9, "eval_result": [{"cause_line_score": 1, "effect_line_score": 0, "error_type_score": 0, "error_message_score": 0.5, "error_message_eval_reason": "The error description in the LLM Output, 'ValueError: width and height must be positive values', is partially correct. The true error is related to invalid axis limits which also stem from an invalid figsize (0 height), hence it contains relevant information but is incomplete and partly misleading."}, {"cause_line_score": 1, "effect_line_score": 1, "error_type_score": 1, "error_message_score": 1.0, "error_message_eval_reason": "The error message in the LLM Output is an exact match to the Ground Truth, including all key details regarding the IndexError."}, {"cause_line_score": 1, "effect_line_score": 0, "error_type_score": 1, "error_message_score": 1.0, "error_message_eval_reason": "The error message in the LLM output exactly matches the error message in the ground truth, including the error type and the detailed message about the 'numpy.ndarray' object not being callable."}, {"cause_line_score": 1, "effect_line_score": 1, "error_type_score": 0, "error_message_score": 0.75, "error_message_eval_reason": "The LLM Output error message differs in language from the Ground Truth but conveys a similar issue regarding the dimensions of 'y'. The GT mentions 'ValueError: 'y1' is not 1-dimensional' while the LLM states 'ValueError: x and y must have the same length'. The core issue of dimension mismatch is identified, but the message details differ, warranting a 0.75 score."}, {"cause_line_score": 1, "effect_line_score": 1, "error_type_score": 1, "error_message_score": 0.75, "error_message_eval_reason": "The error message in the LLM Output is mostly correct but includes slight rephrasing and an additional concept, while still capturing the key details about the valid options."}, {"cause_line_score": 0, "effect_line_score": 1, "error_type_score": 0, "error_message_score": 0.5, "error_message_eval_reason": "The error message provided by the LLM is partially correct. It does indicate that there is an issue with the 'get_verts()' method of the 'Polygon' object, which aligns with the GT in terms of there being a method-related problem. However, it does not match the GT's key details, which state that the issue is related to the patch type expectation ('TypeError: 'p' must be an instance of matplotlib.patches.Patch, not a numpy.ndarray')."}, {"cause_line_score": 1, "effect_line_score": 1, "error_type_score": 0, "error_message_score": 0.0, "error_message_eval_reason": "The error message in the LLM output is completely incorrect. The Ground Truth specifies that the error is a NameError ('NameError: name 'pd' is not defined'), while the LLM output incorrectly identifies the error as a TypeError ('TypeError: savefig() argument must be a str, not 'DataFrame''). These errors are not related."}, {"cause_line_score": 0, "effect_line_score": 0, "error_type_score": 0, "error_message_score": 0.0, "error_message_eval_reason": "The LLM error message is completely irrelevant to the Ground Truth error message, which is about a missing file."}, {"cause_line_score": 0, "effect_line_score": 0, "error_type_score": 0, "error_message_score": 0.0, "error_message_eval_reason": "The error message provided in the LLM output is 'IndexError: list index out of range', which is completely irrelevant to the Ground Truth error message 'FileNotFoundError: [Errno 2] No such file or directory: 'data.csv''. Hence, it receives the lowest possible score."}, {"cause_line_score": 0, "effect_line_score": 0, "error_type_score": 0, "error_message_score": 0.0, "error_message_eval_reason": "The error message in the LLM Output ('AxesSubplot' object has no attribute 'add_patch') is completely irrelevant to the error message in the Ground Truth (FileNotFoundError: [Errno 2] No such file or directory: 'data.csv')."}, {"cause_line_score": 0, "effect_line_score": 0, "error_type_score": 0, "error_message_score": 0.0, "error_message_eval_reason": "The error description in the LLM Output ('KeyError: 'column_name'') is completely irrelevant or incorrect compared to the Ground Truth ('FileNotFoundError: [Errno 2] No such file or directory: 'data.csv''). Therefore, it receives a score of 0.0."}, {"cause_line_score": 0, "effect_line_score": 0, "error_type_score": 0, "error_message_score": 0.0, "error_message_eval_reason": "The error description 'FileNotFoundError: [Errno 2] No such file or directory: 'data.csv'' in the Ground Truth does not match 'hatch' is not a valid keyword argument for Polygon' in the LLM Output, which is completely irrelevant. Thus, a score of 0.0 is assigned."}]}
{"id": 10, "eval_result": [{"cause_line_score": 0, "effect_line_score": 1, "error_type_score": 1, "error_message_score": 0.75, "error_message_eval_reason": "The error description in the LLM output 'NameError: name 'z-axis' is not defined' is mostly correct but slightly differs because the GT mentions 'NameError: name 'axis' is not defined'. The LLM output identifies the correct error type (NameError) and closely represents the issue but mentions a slightly different undefined variable."}, {"cause_line_score": 1, "effect_line_score": 1, "error_type_score": 0, "error_message_score": 0.0, "error_message_eval_reason": "The error description provided by the LLM Output is 'ValueError: 'labels' and 'locations' must have the same length', which is completely different from the Ground Truth error 'matplotlib.units.ConversionError: Failed to convert value(s) to axis units: ['3', '10']'. There is no overlap or relevance between the two error messages."}, {"cause_line_score": 0, "effect_line_score": 1, "error_type_score": 0, "error_message_score": 0.0, "error_message_eval_reason": "The error message provided by the LLM Output is completely different from the Ground Truth. The GT error is a 'NotImplementedError: Derived must override', indicating that an derived class method that isn't implemented properly is being called, while the LLM Output shows a 'TypeError: 'Patch' object is not callable', indicating a completely different issue related to calling an object of a wrong type."}]}
{"id": 11, "eval_result": [{"cause_line_score": 1, "effect_line_score": 1, "error_type_score": 0, "error_message_score": 0.0, "error_message_eval_reason": "The LLM's error message describes a completely different issue ('Axes' object has no attribute 'relim') than the Ground Truth (NameError: name 'ax' is not defined). The error descriptions are not related and do not match any details from each other."}]}
{"id": 12, "eval_result": [{"cause_line_score": 0, "effect_line_score": 0, "error_type_score": 0, "error_message_score": 0.75, "error_message_eval_reason": "The LLM correctly identified the issue being related to an incorrect module or attribute reference (module 'matplotlib.matplotline' has no attribute 'use'). However, the exact error message provided in the ground truth indicates a 'NameError' for 'matplotline' with an additional suggestion (Did you mean: 'matplotlib'?). The LLM's output mentions 'Module has no attribute' which is close but not an exact match. Therefore, it deserves a score of 0.75 as it is mostly correct but lacks the detailed error message provided in the ground truth."}, {"cause_line_score": 0, "effect_line_score": 0, "error_type_score": 0, "error_message_score": 0.0, "error_message_eval_reason": "The error message provided by the LLM ('ValueError: 'x' and 'y' must have the same length') is completely different and unrelated to the Ground Truth error message ('NameError: name 'matplotplot' is not defined. Did you mean: 'matplotlib'?'). There is no connection between the errors described, so the LLM output does not match the ground truth in any aspect."}, {"cause_line_score": 0, "effect_line_score": 0, "error_type_score": 0, "error_message_score": 0.0, "error_message_eval_reason": "The error message in the LLM output is 'AttributeError: 'AxesSubplot' object has no attribute 'plot'', which is completely different from the ground truth error message 'AttributeError: 'bool' object has no attribute 'size''."}, {"cause_line_score": 0, "effect_line_score": 0, "error_type_score": 0, "error_message_score": 0.0, "error_message_eval_reason": "The Ground Truth mentions an 'UnboundLocalError' for the variable 'ax'. The LLM mentioned a 'TypeError', which is an entirely different error type. Thus, there is no match between the error types or messages. Furthermore, the 'cause_line' and 'effect_line' in the LLM's output do not match the 'main()' line stated in the Ground Truth."}]}
{"id": 13, "eval_result": [{"cause_line_score": 0, "effect_line_score": 0, "error_type_score": 0, "error_message_score": 0.0, "error_message_eval_reason": "The error description provided by the LLM ('ValueError: Can not put more than one figure manager for a given figure') does not match the ground truth ('TypeError: only length-1 arrays can be converted to Python scalars'). The error message is completely irrelevant to the error described in the ground truth."}, {"cause_line_score": 0, "effect_line_score": 0, "error_type_score": 0, "error_message_score": 0.0, "error_message_eval_reason": "The error description provided by the LLM ('RuntimeError: Can not put single artist in figure when using Agg backend') is completely different from the Ground Truth error ('TypeError: cannot unpack non-iterable Axes object'). The errors have no relation to each other."}, {"cause_line_score": 1, "effect_line_score": 0, "error_type_score": 0, "error_message_score": 0.75, "error_message_eval_reason": "The error message correctly identifies that 'matplotlab' is not defined and suggests it may be a name error. However, it mentions the error type as ImportError instead of NameError, and it doesn't include the suggestion for 'matplotlib'. Therefore, it is mostly correct but lacks some details."}, {"cause_line_score": 1, "effect_line_score": 1, "error_type_score": 0, "error_message_score": 0.0, "error_message_eval_reason": "The LLM provided an incorrect error message that is not aligned with the Ground Truth. The Ground Truth specifies a 'TypeError' indicating an unexpected keyword argument 'ax', while the LLM incorrectly indicates an 'AttributeError' where 'AxesSubplot' supposedly has no attribute 'to_string'."}]}
{"id": 14, "eval_result": [{"cause_line_score": 0, "effect_line_score": 0, "error_type_score": 0, "error_message_score": 0.0, "error_message_eval_reason": "The error message 'AttributeError: 'Series' object has no attribute 'values'' is completely irrelevant to the Ground Truth error message 'NameError: name 'pd' is not defined. Did you mean: 'id'?'. The Ground Truth error indicates an issue with 'pd' not being defined, while the LLM's error message points to an attribute error on a 'Series' object."}, {"cause_line_score": 1, "effect_line_score": 0, "error_type_score": 0, "error_message_score": 0.0, "error_message_eval_reason": "The LLM's error message indicates an 'AttributeError' related to the 'pd' module not having a 'Series' attribute, which is completely different from the 'NameError' indicating 'pd' is not defined in the Ground Truth error message."}, {"cause_line_score": 1, "effect_line_score": 0, "error_type_score": 0, "error_message_score": 0.5, "error_message_eval_reason": "The error description is partially correct but contains incomplete information. The LLM Output correctly identifies that the figure size is an issue, but it fails to match the specific error message in the Ground Truth ('tile cannot extend outside image'). Instead, it provides a different, yet related error ('figure size must be positive length in both dimensions')."}, {"cause_line_score": 1, "effect_line_score": 0, "error_type_score": 0, "error_message_score": 0.0, "error_message_eval_reason": "The LLM Output's error message 'Axes3D' object has no attribute 'bar' is completely irrelevant to the Ground Truth error message of 'ValueError: Unknown projection '2d'. The provided error description does not mention or relate to the projection issue identified in the Ground Truth."}, {"cause_line_score": 0, "effect_line_score": 1, "error_type_score": 0, "error_message_score": 0.25, "error_message_eval_reason": "The error message provided by the LLM Output ('IndexError: too many indices for array: array is 1-dimensional, but 2 were indexed') is only loosely related to the ground truth error message ('ValueError: shape mismatch: objects cannot be broadcast to a single shape.  Mismatch is between arg 0 with shape (30,) and arg 1 with shape (4,).'). While both error messages pertain to a problem with array shapes or dimensions, they are fundamentally different types of errors and affect different aspects of the code."}, {"cause_line_score": 0, "effect_line_score": 0, "error_type_score": 0, "error_message_score": 0.0, "error_message_eval_reason": "The error message in LLM output talks about `IndexError` with the message 'index 4 is out of bounds for axis 0 with size 4', which is completely different from the GT error which is a `TypeError` with the message 'can't multiply sequence by non-int of type numpy.float64'. Therefore, the error message is completely irrelevant or incorrect."}, {"cause_line_score": 0, "effect_line_score": 0, "error_type_score": 0, "error_message_score": 0.0, "error_message_eval_reason": "The LLM Output's cause and effect lines do not match the Ground Truth at all. The error type 'IndexError' in the LLM Output does not match the 'KeyError' in the Ground Truth. Additionally, the error message 'too many indices for array: array is 1-dimensional, but 2 were indexed' is completely unrelated to 'KeyError: 'layer'' in the GT."}, {"cause_line_score": 1, "effect_line_score": 1, "error_type_score": 0, "error_message_score": 0.0, "error_message_eval_reason": "The error description in the LLM Output ('Bar3D' object has no attribute 'set_linewidth') is completely irrelevant or incorrect compared to the Ground Truth ('TypeError: Axes3D.bar3d() missing 1 required positional argument: 'dz'). The LLM output describes a different type of error that is not related to the provided code or error message in the Ground Truth."}]}
{"id": 15, "eval_result": [{"cause_line_score": 1, "effect_line_score": 0, "error_type_score": 0, "error_message_score": 0.0, "error_message_eval_reason": "The error message from the LLM Output ('AttributeError: 'Series' object has no attribute 'cos'') is entirely different and irrelevant compared to the Ground Truth error message ('NameError: name 'pd' is not defined.')."}, {"cause_line_score": 1, "effect_line_score": 0, "error_type_score": 0, "error_message_score": 0.0, "error_message_eval_reason": "The error message in the LLM output is 'IndexError: too many indices for array: array is 1-dimensional, but 2 were indexed' which is completely different from the ground truth error message 'ValueError: operands could not be broadcast together with remapped shapes [original->remapped]: (127,)  and requested shape (127,1)'. Therefore, the score is 0.0."}, {"cause_line_score": 1, "effect_line_score": 0, "error_type_score": 0, "error_message_score": 0.0, "error_message_eval_reason": "The error message in the LLM Output ('ValueError: x and y must have the same length') is completely irrelevant to the actual error message in the Ground Truth ('ValueError: setting an array element with a sequence. The requested array has an inhomogeneous shape after 3 dimensions...'). The actual error is related to array shape mismatch, whereas the LLM Output suggests a length mismatch between x and y, which is a different issue."}, {"cause_line_score": 1, "effect_line_score": 0, "error_type_score": 0, "error_message_score": 0.25, "error_message_eval_reason": "The error message from the LLM mentions a shape alignment issue, which is somewhat related to the original ValueError. However, the specific details and context of the error do not match the Ground Truth message about dimensions and axis remapping. The context of the error is completely different, leading to a loosely related, but incorrect, description."}, {"cause_line_score": 1, "effect_line_score": 0, "error_type_score": 0, "error_message_score": 0.0, "error_message_eval_reason": "The error message in the LLM output is completely different from the ground truth. The ground truth error message is 'numpy.linalg.LinAlgError: Singular matrix' which is due to a matrix singularity caused by the figure size having a zero dimension. The LLM output error message 'ValueError: figure size must be positive finite not (0, 6)' is completely unrelated to the ground truth error and indicates a different issue altogether."}, {"cause_line_score": 1, "effect_line_score": 1, "error_type_score": 0, "error_message_score": 0.0, "error_message_eval_reason": "The error message described in the LLM Output ('IndexError: too many indices for array: array is 1-dimensional, but 3 were indexed') is completely different from the one in the Ground Truth ('TypeError: slice indices must be integers or None or have an __index__ method'). The two errors are not related, and therefore the score is 0.0."}, {"cause_line_score": 1, "effect_line_score": 0, "error_type_score": 0, "error_message_score": 0.0, "error_message_eval_reason": "The error message provided by the LLM ('Axes3D' object has no attribute 'set_xlabel') is completely different from the Ground Truth ('NameError: name 'pd' is not defined. Did you mean: 'id'?'). The LLM's error message is irrelevant to the actual error."}, {"cause_line_score": 1, "effect_line_score": 1, "error_type_score": 0, "error_message_score": 0.0, "error_message_eval_reason": "The error message from the LLM output mentions an incorrect attribute error related to 'Series' object and 'iloc', which is not the same as the NameError indicated in the ground truth. Therefore, the error description provided by the LLM is completely irrelevant to the actual error."}, {"cause_line_score": 1, "effect_line_score": 1, "error_type_score": 0, "error_message_score": 0.0, "error_message_eval_reason": "The error message in the LLM Output is 'AttributeError: 'DataFrame' object has no attribute 'savefig'', which is completely irrelevant to the ground truth error message 'NameError: name 'pd' is not defined. Did you mean: 'id'?'. The ground truth error message indicates a NameError whereas the LLM Output error message indicates an AttributeError."}, {"cause_line_score": 1, "effect_line_score": 0, "error_type_score": 0, "error_message_score": 0.0, "error_message_eval_reason": "The LLM output error message is 'TypeError: unhashable type: numpy.ndarray', which is entirely different and unrelated to the ground truth error message 'ValueError: The truth value of an array with more than one element is ambiguous. Use a.any() or a.all()'."}, {"cause_line_score": 0, "effect_line_score": 0, "error_type_score": 0, "error_message_score": 0.0, "error_message_eval_reason": "The error message provided by the LLM Output ('Axes3D' object has no attribute 'errorbar') is completely irrelevant to the actual error message in the Ground Truth ('IndexError: too many indices for array: array is 1-dimensional, but 4 were indexed'). They are two different types of errors and relate to different issues in the code."}, {"cause_line_score": 0, "effect_line_score": 0, "error_type_score": 0, "error_message_score": 0.0, "error_message_eval_reason": "The error description in the LLM Output ('TypeError: 'in <sequence>' requires a sequence') is completely irrelevant or incorrect compared to the Ground Truth ('ValueError: The truth value of an array with more than one element is ambiguous. Use a.any() or a.all()'). There is no overlap in error type or description."}, {"cause_line_score": 0, "effect_line_score": 0, "error_type_score": 0, "error_message_score": 0.0, "error_message_eval_reason": "The LLM output reflects an AttributeError related to matplotlib, which is completely unrelated to the FileNotFoundError in the ground truth. There is no similarity in the cause, effect, or error messages provided, hence a score of 0.0 for error message matching."}]}
{"id": 16, "eval_result": [{"cause_line_score": 1, "effect_line_score": 0, "error_type_score": 0, "error_message_score": 0.0, "error_message_eval_reason": "The error message 'ValueError: Negative dimensions are not allowed' is different from 'ValueError: cannot convert float NaN to integer'. The error type (ValueError) is the same, but the specific descriptions and their contexts are entirely different, thus scoring 0.0."}, {"cause_line_score": 1, "effect_line_score": 1, "error_type_score": 1, "error_message_score": 0.0, "error_message_eval_reason": "The error message provided by the LLM is 'ValueError: cannot reshape array of size 100 into shape (-1, 1)', which is factually incorrect and does not align with the Ground Truth error message 'ValueError: operands could not be broadcast together with shapes (10000,1,6) (600,4)'. The key details about the broadcast shapes and the operand mismatch are missing."}, {"cause_line_score": 1, "effect_line_score": 1, "error_type_score": 0, "error_message_score": 0.0, "error_message_eval_reason": "The error message provided by the LLM ('Series' object has no attribute 'describe') is completely incorrect. The correct error message is related to the 'NameError' due to the missing import for 'pd' (pandas). Therefore, the LLM's error message does not relate to the actual error and receives a score of 0.0."}, {"cause_line_score": 1, "effect_line_score": 1, "error_type_score": 0, "error_message_score": 0.0, "error_message_eval_reason": "The error message provided by the LLM is 'Series' object has no attribute 'mean', which is completely incorrect compared to the ground truth of 'NameError: name 'pd' is not defined. Did you mean: 'id'?'."}, {"cause_line_score": 1, "effect_line_score": 1, "error_type_score": 0, "error_message_score": 0.0, "error_message_eval_reason": "The error type and message provided by the LLM output do not match the Ground Truth. The provided error message is about an AttributeError related to 'set_zlabel', while the Ground Truth specifies a NameError due to 'pd' not being defined."}, {"cause_line_score": 1, "effect_line_score": 1, "error_type_score": 0, "error_message_score": 0.0, "error_message_eval_reason": "The LLM's error message indicates an 'AttributeError' while the Ground Truth specifies a 'NameError'. This is a completely different error type with unrelated causes and consequences in the code."}, {"cause_line_score": 0, "effect_line_score": 0, "error_type_score": 0, "error_message_score": 0.5, "error_message_eval_reason": "The error description in the LLM Output (shapes (9,9) and (10,10) not aligned: 9 (dim 1) != 10 (dim 0)) is partially correct but contains different details than the Ground Truth error message (shape mismatch: objects cannot be broadcast to a single shape. Mismatch is between arg 0 with shape (81,) and arg 3 with shape (72,)). Both messages describe shape mismatches but involve different shapes and specific differences."}, {"cause_line_score": 0, "effect_line_score": 0, "error_type_score": 0, "error_message_score": 0.0, "error_message_eval_reason": "The error message given by the LLM Output ('shapes (10,10) and (9,) not aligned') does not match the Ground Truth ('too many values to unpack (expected 2)'). The two error types are also different: the LLM identified a shape misalignment issue, while the Ground Truth indicated an unpacking issue. Therefore, the error message is completely irrelevant to the Ground Truth error."}, {"cause_line_score": 1, "effect_line_score": 1, "error_type_score": 0, "error_message_score": 0.0, "error_message_eval_reason": "The error message given by the LLM Output ('too many values to unpack (expected 2)') is completely different from the Ground Truth ('operands could not be broadcast together with shapes'). There is no similarity in terms of the error type or context."}, {"cause_line_score": 0, "effect_line_score": 0, "error_type_score": 0, "error_message_score": 0.0, "error_message_eval_reason": "The error message provided in the LLM's output: 'ValueError: too many values to unpack (expected 2)' does not match the error in the Ground Truth: 'AttributeError: module 'matplotlib.pyplot' has no attribute 'zlabel'. Did you mean: 'clabel'?' The LLM identified a completely different issue and error message, thus the score is 0.0."}, {"cause_line_score": 1, "effect_line_score": 1, "error_type_score": 1, "error_message_score": 0.0, "error_message_eval_reason": "The error message provided in the LLM Output does not match the Ground Truth. The shapes in the error message in GT are (100,1,6) (60,4) whereas in the LLM Output they are (9,) (9,) (10,10). These shapes are completely different, which makes the error message from the LLM irrelevant to the actual error described in the GT."}]}
{"id": 17, "eval_result": [{"cause_line_score": 0, "effect_line_score": 0, "error_type_score": 0, "error_message_score": 0.0, "error_message_eval_reason": "The error message in the LLM output is 'ValueError: operands could not be broadcast together with shapes (1000,) (1000,) (1000,)', which is completely irrelevant to the ground truth error message 'ValueError: dpi must be positive'."}, {"cause_line_score": 0, "effect_line_score": 0, "error_type_score": 0, "error_message_score": 0.0, "error_message_eval_reason": "The error description in the LLM Output ('ValueError: operands could not be broadcast together with shapes (1000,) (1000,)') is completely irrelevant to the Ground Truth, which is about a FileNotFoundError for 'data.csv'. There is no connection in terms of cause, effect, or error message type between the provided GT and the LLM Output."}]}
{"id": 18, "eval_result": [{"cause_line_score": 1, "effect_line_score": 1, "error_type_score": 0, "error_message_score": 0.5, "error_message_eval_reason": "The LLM output identifies a type of IndexError, which is correct, but specifies 'too many indices for array' instead of the more accurate 'index 10000 is out of bounds for axis 0 with size 10000'. This phrasing captures the general nature of the error but misses key specifics outlined in the ground truth."}, {"cause_line_score": 1, "effect_line_score": 1, "error_type_score": 1, "error_message_score": 0.75, "error_message_eval_reason": "The LLM's output captures the main essence of the error \u2013 a broadcasting issue due to shape mismatch between the arrays. However, the exact error message from the GT mentions 'ValueError: operands could not be broadcast together with remapped shapes [original->remapped]: (10001,)  and requested shape (10001,1)', whereas the LLM's error message focuses on 'ValueError: x and y must have same first dimension, but have shapes (10001, 1) and (10001,)'. Both are correct, and the LLM's message provides relevant information, but it lacks the specific remapped shapes detail present in the GT."}, {"cause_line_score": 0, "effect_line_score": 0, "error_type_score": 0, "error_message_score": 0.0, "error_message_eval_reason": "The error message 'Cannot use show() with the 'Agg' backend' is completely irrelevant to the 'ValueError: dpi must be positive' error in the Ground Truth."}, {"cause_line_score": 0, "effect_line_score": 0, "error_type_score": 1, "error_message_score": 1.0, "error_message_eval_reason": "Both the Ground Truth and LLM Output identified the error as a `TypeError` with the description \"'float' (or 'numpy.float64') object is not subscriptable\", which matches exactly."}]}
{"id": 19, "eval_result": [{"cause_line_score": 1, "effect_line_score": 0, "error_type_score": 0, "error_message_score": 0.0, "error_message_eval_reason": "The error message provided by the LLM Output does not match the Ground Truth. The Ground Truth error is 'TypeError: projection must be a string, None or implement a _as_mpl_axes method, not 3' which is related to the 'projection' parameter, whereas the LLM Output mentions 'TypeError: plot_surface() missing 1 required positional argument: 'Z'', which is related to the 'plot_surface' method and an incorrect/missing argument."}, {"cause_line_score": 0, "effect_line_score": 0, "error_type_score": 0, "error_message_score": 0.0, "error_message_eval_reason": "The error description provided by the LLM ('ValueError: 'x' and 'y' must have the same dimensions') is completely irrelevant to the error described in the Ground Truth ('ValueError: dpi must be positive'). Hence, the score is 0.0."}, {"cause_line_score": 1, "effect_line_score": 1, "error_type_score": 1, "error_message_score": 0.75, "error_message_eval_reason": "The error description in the LLM output is mostly correct, mentioning that the object involved has no attribute 'plot_surface'; however, it specifies 'AxesSubplot' instead of 'Axes', which is a minor distinction."}, {"cause_line_score": 0, "effect_line_score": 0, "error_type_score": 0, "error_message_score": 0.0, "error_message_eval_reason": "The error message in the LLM Output ('AttributeError: 'AxesSubplot' object has no attribute 'plot_surface'') does not match the Ground Truth error message ('FileNotFoundError: data.csv not found.'). The two errors are completely different, one being a FileNotFoundError and the other being an AttributeError. Hence, the error description is completely irrelevant to the provided Ground Truth."}]}
