{"id": 0, "eval_result": [[{"cause_line_score": 0, "effect_line_score": 0, "error_type_score": 0, "error_message_score": 0.0, "error_message_eval_reason": "No holistic match found with any error instance in Ground Truth Errors list."}, {"cause_line_score": 1, "effect_line_score": 1, "error_type_score": 0, "error_message_score": 0.0, "error_message_eval_reason": "The LLM Output Error cause line and effect line perfectly match the second error instance (Ground Truth Error 2). However, the error message 'TypeError: 'auto' is not a valid value for dpi' does not match 'TypeError: can't multiply sequence by non-int of type 'numpy.float64'' from the same error instance. Therefore, the error message is completely irrelevant, and the error type also does not match."}]]}
{"id": 1, "eval_result": [[{"cause_line_score": 1, "effect_line_score": 1, "error_type_score": 0, "error_message_score": 0.0, "error_message_eval_reason": "No holistic match found with any error instance in Ground Truth Errors list. The cause line and effect line match Ground Truth Error 1, but the error type and error message do not correspond to the Ground Truth error message, which is 'ValueError: X must have 2 or fewer dimensions'. The error type and message provided by the LLM output is completely irrelevant to any specific error instance described in the ground truth errors."}, {"cause_line_score": 0, "effect_line_score": 0, "error_type_score": 0, "error_message_score": 0.0, "error_message_eval_reason": "No holistic match found with any error instance in Ground Truth Errors list. The cause line and effect line from the LLM Output error matched with Ground Truth Error 2, but the error type and error message did not match. Ground Truth Error 2 described a 'ValueError' with a different error message ('not enough values to unpack (expected 2, got 1)'), whereas the LLM Output error was a 'TypeError' with a completely different message ('unhashable type: 'list'')."}]]}
{"id": 2, "eval_result": [[{"cause_line_score": 0, "effect_line_score": 0, "error_type_score": 0, "error_message_score": 0.0, "error_message_eval_reason": "No holistic match found with any error instance in Ground Truth Errors list."}]]}
{"id": 3, "eval_result": [[{"cause_line_score": 0, "effect_line_score": 0, "error_type_score": 0, "error_message_score": 0.0, "error_message_eval_reason": "No holistic match found with any error instance in Ground Truth Errors list."}, {"cause_line_score": 1, "effect_line_score": 0, "error_type_score": 0, "error_message_score": 0.0, "error_message_eval_reason": "The cause line in the LLM Output exactly matches the cause line of Ground Truth Error 1. However, the effect line does not match any effect line in the Ground Truth Errors list. This discrepancy means that there is no holistic match found with any error instance in the Ground Truth Errors list, resulting in a score of 0 for effect line, error type, and error message."}]]}
{"id": 4, "eval_result": [[{"cause_line_score": 1, "effect_line_score": 0, "error_type_score": 0, "error_message_score": 0.5, "error_message_eval_reason": "The cause line exactly matches Ground Truth Error 1. However, the effect line 'axs[0, 0].plot(z, w, 'r')' from LLM Output does not match the effect line 'w = pd.Series(np.linspace(-10, 10, 400))  # Modified line' from Ground Truth Error 1. Additionally, the error type in the LLM Output is not clearly specified, while in Ground Truth Error 1, it is a NameError. The error message 'NameError: name 'pd' is not defined' partially matches Ground Truth Error 1's message 'NameError: name 'pd' is not defined. Did you mean: 'id'?', but lacks the additional suggestion 'Did you mean: 'id'?'. Therefore, it scores 0.5 for partial correctness."}, {"cause_line_score": 0, "effect_line_score": 0, "error_type_score": 0, "error_message_score": 0.0, "error_message_eval_reason": "No holistic match found with any error instance in Ground Truth Errors list."}]]}
{"id": 5, "eval_result": [[{"cause_line_score": 1, "effect_line_score": 0, "error_type_score": 0, "error_message_score": 0.0, "error_message_eval_reason": "No holistic match found with any error instance in Ground Truth Errors list."}]]}
{"id": 6, "eval_result": [[{"cause_line_score": 1, "effect_line_score": 0, "error_type_score": 1, "error_message_score": 1.0, "error_message_eval_reason": "Holistically matched Ground Truth Error 2 perfectly for cause_line, error_type, and error_message but did not match the effect_line."}]]}
{"id": 7, "eval_result": [[{"cause_line_score": 0, "effect_line_score": 0, "error_type_score": 0, "error_message_score": 0.0, "error_message_eval_reason": "No holistic match found with any error instance in Ground Truth Errors list."}, {"cause_line_score": 1, "effect_line_score": 1, "error_type_score": 1, "error_message_score": 0.75, "error_message_eval_reason": "Holistically matched Ground Truth Error 1 with minor variations in the error message. The description 'The lengths of z and w do not match, resulting in incorrect plot behavior' closely matches 'x and y must have same first dimension, but have shapes (50,) and (400,)' but lacks specific details about the shapes."}]]}
{"id": 8, "eval_result": [[{"cause_line_score": 0, "effect_line_score": 0, "error_type_score": 0, "error_message_score": 0.0, "error_message_eval_reason": "No holistic match found with any error instance in Ground Truth Errors list. The cause and effect lines in the LLM Output match those in the Ground Truth Errors list, but the error type and the error message are entirely different. The Ground Truth Errors list indicates a NameError, while the LLM Output indicates an AttributeError."}, {"cause_line_score": 0, "effect_line_score": 0, "error_type_score": 0, "error_message_score": 0.0, "error_message_eval_reason": "No holistic match found with any error instance in Ground Truth Errors list."}]]}
{"id": 9, "eval_result": [[{"cause_line_score": 1, "effect_line_score": 0, "error_type_score": 0, "error_message_score": 0.0, "error_message_eval_reason": "The LLM Output cause line matches Ground Truth Error 1's cause line exactly. However, the effect line does not match either Ground Truth Error 1 or Ground Truth Error 2's effect lines. Furthermore, the error type 'IndexError' in the LLM Output does not match the 'ValueError' or 'NameError' in the Ground Truth Errors. Lastly, the error message 'too many values to unpack (expected 3)' is completely irrelevant compared to the error messages in the Ground Truth Errors list."}, {"cause_line_score": 1, "effect_line_score": 1, "error_type_score": 0, "error_message_score": 0.0, "error_message_eval_reason": "Cause and effect lines matched Ground Truth Error 2 perfectly. However, the error type did not match (AttributeError vs. NameError). The error message was completely irrelevant compared to the error message in Ground Truth Error 2."}]]}
{"id": 10, "eval_result": [[{"cause_line_score": 1, "effect_line_score": 1, "error_type_score": 0, "error_message_score": 0.0, "error_message_eval_reason": "The cause line and effect line exactly match the lines in Ground Truth Error 1, but the error type 'AttributeError' does not match the error type 'NameError' in Ground Truth Error 1. Additionally, the error message 'AttributeError: 'AxesSubplot' object has no attribute 'set_title'' is completely irrelevant compared to the error message 'NameError: name 'pd' is not defined. Did you mean: 'd'?' in Ground Truth Error 1 and also unrelated to the error messages in Ground Truth Error 2."}, {"cause_line_score": 0, "effect_line_score": 0, "error_type_score": 0, "error_message_score": 0.0, "error_message_eval_reason": "No holistic match found with any error instance in Ground Truth Errors list."}]]}
{"id": 11, "eval_result": [[{"cause_line_score": 1, "effect_line_score": 1, "error_type_score": 0, "error_message_score": 0.0, "error_message_eval_reason": "The cause and effect lines in the LLM output error match exactly with Ground Truth Error 1: 'axes[0].set_title(pd.DataFrame(data).describe())'. However, the error type 'TypeError' in the LLM output does not match the error type 'NameError' in Ground Truth Error 1. Furthermore, the error message in the LLM output 'TypeError: 'AxesSubplot' object is not callable' is completely irrelevant to the error message in Ground Truth Error 1: 'NameError: name 'pd' is not defined. Did you mean: 'd'?'. Therefore, the error message score is 0.0."}, {"cause_line_score": 1, "effect_line_score": 0, "error_type_score": 0, "error_message_score": 0.0, "error_message_eval_reason": "No holistic match found with any error instance in Ground Truth Errors list."}]]}
{"id": 12, "eval_result": [[{"cause_line_score": 1, "effect_line_score": 1, "error_type_score": 1, "error_message_score": 1.0, "error_message_eval_reason": "Holistically matched Ground Truth Error 1 perfectly."}, {"cause_line_score": 0, "effect_line_score": 0, "error_type_score": 0, "error_message_score": 0.0, "error_message_eval_reason": "No holistic match found with any error instance in Ground Truth Errors list."}]]}
{"id": 13, "eval_result": [[{"cause_line_score": 0, "effect_line_score": 0, "error_type_score": 0, "error_message_score": 0.0, "error_message_eval_reason": "No holistic match found with any error instance in Ground Truth Errors list."}, {"cause_line_score": 0, "effect_line_score": 0, "error_type_score": 0, "error_message_score": 0.0, "error_message_eval_reason": "No holistic match found with any error instance in Ground Truth Errors list."}]]}
{"id": 14, "eval_result": [[{"cause_line_score": 1, "effect_line_score": 0, "error_type_score": 0, "error_message_score": 0.0, "error_message_eval_reason": "No holistic match found with any error instance in Ground Truth Errors list."}]]}
{"id": 15, "eval_result": [[{"cause_line_score": 1, "effect_line_score": 0, "error_type_score": 0, "error_message_score": 0.0, "error_message_eval_reason": "No holistic match found with any error instance in Ground Truth Errors list."}]]}
{"id": 16, "eval_result": [[{"cause_line_score": 0, "effect_line_score": 0, "error_type_score": 0, "error_message_score": 0.0, "error_message_eval_reason": "No holistic match found with any error instance in Ground Truth Errors list. The cause line in the LLM Output ('matplotlib.use('tkagg')') does not match any cause line in Ground Truth Errors. Additionally, the error message in the LLM Output ('AttributeError: module 'matplotlib' has no attribute 'use'') is completely irrelevant compared to the error messages in the ground truth errors."}, {"cause_line_score": 1, "effect_line_score": 1, "error_type_score": 1, "error_message_score": 0.0, "error_message_eval_reason": "No holistic match found with any error instance in Ground Truth Errors list."}]]}
{"id": 17, "eval_result": [[{"cause_line_score": 0, "effect_line_score": 0, "error_type_score": 0, "error_message_score": 0.0, "error_message_eval_reason": "No holistic match found with any error instance in Ground Truth Errors list."}, {"cause_line_score": 1, "effect_line_score": 0, "error_type_score": 1, "error_message_score": 0.75, "error_message_eval_reason": "Cause and Error Type matched Ground Truth Error 2, but the error message is mostly correct (missing minor details) \u2013 hence the 0.75 score."}]]}
{"id": 18, "eval_result": [[{"cause_line_score": 1, "effect_line_score": 1, "error_type_score": 0, "error_message_score": 0.0, "error_message_eval_reason": "The LLM's output error analysis matches the cause and effect lines of Ground Truth Error 1 perfectly. However, the error type does not match, as Ground Truth Error 1 has a 'ValueError: shape mismatch...' message, while the LLM's output mentions 'ValueError: too many values to unpack (expected 2)', which is completely irrelevant. Thus, the error type and error message do not correspond to any error instance in the Ground Truth Errors list."}, {"cause_line_score": 1, "effect_line_score": 0, "error_type_score": 0, "error_message_score": 0.0, "error_message_eval_reason": "The cause line exactly matches with Ground Truth Error 2. However, the effect line does not match. The Ground Truth points to the same line for effect as the cause in Ground Truth Error 2, but the LLM's output error suggests a different effect line. Additionally, the error types 'NameError' (Ground Truth Error 2) and 'TypeError' (LLM output) do not match. The error message descriptions are completely different as well. Thus, there is no holistic match found with any error instance in the Ground Truth Errors list."}]]}
{"id": 19, "eval_result": [[{"cause_line_score": 0, "effect_line_score": 0, "error_type_score": 0, "error_message_score": 0.0, "error_message_eval_reason": "No holistic match found with any error instance in Ground Truth Errors list."}, {"cause_line_score": 1, "effect_line_score": 1, "error_type_score": 0, "error_message_score": 0.0, "error_message_eval_reason": "The LLM Output error's cause line 'radii = np.random.rand(N, 10)' and effect line 'ax.bar(theta, radii, width=width, bottom=0.0, color=colors, alpha=0.5)' exactly match Ground Truth Error 2. However, the error message and error type do not match. Ground Truth Error 2's error message is 'ValueError: shape mismatch: objects cannot be broadcast to a single shape. Mismatch is between arg 0 with shape (20,) and arg 1 with shape (20, 10).', while the LLM Output error message is 'ValueError: x and y must have the same length.' The error type from the Ground Truth Error 2 is 'shape mismatch' while the LLM Output mentions a length mismatch, which are not the same. Therefore, the error message and error type do not match, leading to a score of 0 for both."}, {"cause_line_score": 1, "effect_line_score": 0, "error_type_score": 0, "error_message_score": 0.0, "error_message_eval_reason": "The LLM's output cause line matches Ground Truth Error 3 perfectly. However, the effect line and the error type do not match any of the Ground Truth errors. The error message is completely irrelevant compared to the provided Ground Truth Error messages. Therefore, the cause line score is 1, but the effect line score, error type score, and error message score are all 0."}]]}
{"id": 20, "eval_result": [[{"cause_line_score": 1, "effect_line_score": 0, "error_type_score": 1, "error_message_score": 0.75, "error_message_eval_reason": "The LLM's detected error cause line 'x2 = pd.Series(np.arange(0.0, 3.0, 0.2))' exactly matches the cause line in Ground Truth Error 1. However, the effect line 'y2 = np.cos(3 * np.pi * x2)' does not match the effect line in Ground Truth Error 1. The error type 'NameError' matches perfectly with Ground Truth Error 1. The error message in the LLM output is mostly correct but lacks the suggestion part 'Did you mean: 'id'?' present in the Ground Truth Error 1 message. Hence, the score assigned for the error message is 0.75."}, {"cause_line_score": 1, "effect_line_score": 0, "error_type_score": 0, "error_message_score": 0.0, "error_message_eval_reason": "The LLM's output cause line 'y2 = np.cos(3 * np.pi * x2)' matches the cause line of Ground Truth Error 2. However, the effect line 'y2 = np.cos(3 * np.pi * x2)' doesn't match any effect line of the same specific error instance (Ground Truth Error 2). The error type 'ValueError' from the LLM's output is correct but the error message 'operands could not be broadcast together with shapes (16,) (150,)' does not match 'x and y must have same first dimension, but have shapes (150,) and (15,)' from Ground Truth Error 2. Therefore, the error message is completely irrelevant."}]]}
{"id": 21, "eval_result": [[{"cause_line_score": 0, "effect_line_score": 0, "error_type_score": 0, "error_message_score": 0.0, "error_message_eval_reason": "No holistic match found with any error instance in Ground Truth Errors list. The LLM's detected error involves a ValueError about figure height, whereas the Ground Truth Errors list contains an IndexError, ValueError related to dimension and property values, and a TypeError unrelated to figure height."}, {"cause_line_score": 0, "effect_line_score": 0, "error_type_score": 0, "error_message_score": 0.0, "error_message_eval_reason": "No holistic match found with any error instance in Ground Truth Errors list. The LLM's cause_line, effect_line, error type, and error message did not correspond to any specific error instance in the Ground Truth Errors."}]]}
{"id": 22, "eval_result": [[{"cause_line_score": 0, "effect_line_score": 0, "error_type_score": 0, "error_message_score": 0.0, "error_message_eval_reason": "No holistic match found with any error instance in the Ground Truth Errors list."}, {"cause_line_score": 1, "effect_line_score": 1, "error_type_score": 0, "error_message_score": 0.0, "error_message_eval_reason": "Ground Truth Error 2: LLM's cause line and effect line 'fig.savefig(pd.DataFrame([['novice_final.png']]))' both match exactly. However, the error type in the Ground Truth is 'NameError' with the message: \"NameError: name 'pd' is not defined. Did you mean: 'id'?\", while the LLM's error type is 'AttributeError' with message: \"AttributeError: 'DataFrame' object has no attribute 'savefig'\". They do not match; thus, no holistic match is found with any specific error instance in the Ground Truth Errors list."}]]}
{"id": 23, "eval_result": [[{"cause_line_score": 1, "effect_line_score": 1, "error_type_score": 0, "error_message_score": 0.75, "error_message_eval_reason": "Holistically matched Ground Truth Error 1 partially. The cause and effect lines match exactly, but the error messages differ slightly in content - the LLM output's message states 'figure size must be positive finite not (8, 0)','which is very close to the actual message 'Axis limits cannot be NaN or Inf', suggesting a mostly correct but slightly varied interpretation of the error."}, {"cause_line_score": 1, "effect_line_score": 0, "error_type_score": 1, "error_message_score": 1.0, "error_message_eval_reason": "LLM's output cause line exactly matched Ground Truth Error 2. However, the effect line 'y = np.cos(x)' did not match the effect line in Ground Truth Error 2 ('x = np.linspace(0, 4 * np.pi, dtype=float)(100)'). The error type ('TypeError') and error message ('TypeError: 'numpy.ndarray' object is not callable') perfectly matched Ground Truth Error 2."}]]}
{"id": 24, "eval_result": [[{"cause_line_score": 1, "effect_line_score": 1, "error_type_score": 0, "error_message_score": 0.0, "error_message_eval_reason": "The cause and effect lines in the LLM Output exactly match the cause and effect lines in Ground Truth Error 1 ('fig = plt.figure(figsize=(8, 0))'). However, the error types are different: the LLM Output gives 'ValueError: figure size width 8.0 must be positive', while Ground Truth Error 1 provides 'ValueError: Axis limits cannot be NaN or Inf'. Therefore, the error message is completely irrelevant, leading to a score of 0 for the error message."}, {"cause_line_score": 1, "effect_line_score": 0, "error_type_score": 1, "error_message_score": 1.0, "error_message_eval_reason": "Holistically matched Ground Truth Error 2 perfectly."}, {"cause_line_score": 0, "effect_line_score": 0, "error_type_score": 0, "error_message_score": 0.0, "error_message_eval_reason": "No holistic match found with any error instance in Ground Truth Errors list."}]]}
{"id": 25, "eval_result": [[{"cause_line_score": 0, "effect_line_score": 0, "error_type_score": 0, "error_message_score": 0.0, "error_message_eval_reason": "No holistic match found with any error instance in Ground Truth Errors list. The LLM's cause line, effect line, and error type do not match exactly with any specific error instance in the Ground Truth Errors. Additionally, the error message 'ValueError: height cannot be zero' does not correspond to any error message provided in the Ground Truth Errors."}, {"cause_line_score": 1, "effect_line_score": 0, "error_type_score": 0, "error_message_score": 0.0, "error_message_eval_reason": "The cause line 'x = np.linspace(0, 4 * \u03c0, dtype=float)(100)' from the LLM Output exactly matches the cause line in Ground Truth Error 3. However, the effect line 'y = np.cos(x)' does not match. The error message 'TypeError: 'numpy.ndarray' object is not callable' from the LLM Output matches the error message in Ground Truth Error 3, but because the effect line did not match, the error type and message do not count towards the holistic scoring. Therefore, the LLM Output did not holistically match any specific error instance in the Ground Truth Errors list."}]]}
{"id": 26, "eval_result": [[{"cause_line_score": 1, "effect_line_score": 0, "error_type_score": 0, "error_message_score": 0.0, "error_message_eval_reason": "The LLM's output cause line matches the cause line of Ground Truth Error 1 ('fig = plt.figure(figsize=(8, 0))'). However, the effect line ('ax5 = fig.add_subplot(grid[2, :])  # Span both columns') does not match the effect line of Ground Truth Error 1 ('fig.savefig('novice_final.png')'). Additionally, the error type in the LLM's output ('ValueError: figure size must be positive finite not (8, 0)') doesn't perfectly match Ground Truth Error 1's error message ('ValueError: Axis limits cannot be NaN or Inf'). Therefore, the error message is completely irrelevant in this context, scoring 0.0 for no holistic match with any specific error instance in the Ground Truth Errors list."}, {"cause_line_score": 1, "effect_line_score": 1, "error_type_score": 0, "error_message_score": 0.0, "error_message_eval_reason": "The cause and effect lines from the LLM output ('fig.savefig(pd.DataFrame([['novice_final.png']])))') exactly match those found in Ground Truth Error 3. However, the error type and message do not match. Ground Truth Error 3 had a 'NameError: name 'pd' is not defined. Did you mean: 'id'?' whereas the LLM's output had an 'AttributeError: 'DataFrame' object has no attribute 'to_string''. Therefore, there is no holistic match with any error instance in the Ground Truth Errors list."}]]}
{"id": 27, "eval_result": [[{"cause_line_score": 1, "effect_line_score": 0, "error_type_score": 0, "error_message_score": 0.0, "error_message_eval_reason": "No holistic match found with any error instance in Ground Truth Errors list."}, {"cause_line_score": 1, "effect_line_score": 0, "error_type_score": 1, "error_message_score": 0.75, "error_message_eval_reason": "The LLM's Output error closely matches Ground Truth Error 3. The cause line and error type match perfectly with Ground Truth Error 3. However, the effect line does not match; LLM's Error analysis mentions 'y = np.cos(x)' as the effect line, while the Ground Truth has the same cause and effect line. The error message also matches the error message from Ground Truth Error 3 but includes minor variations regarding the code context, hence receives a score of 0.75."}, {"cause_line_score": 1, "effect_line_score": 1, "error_type_score": 0, "error_message_score": 0.0, "error_message_eval_reason": "No holistic match found with any error instance in Ground Truth Errors list."}]]}
{"id": 28, "eval_result": [[{"cause_line_score": 1, "effect_line_score": 0, "error_type_score": 0, "error_message_score": 0.0, "error_message_eval_reason": "The error message does not match the Ground Truth Error 1 or any other error instance in the Ground Truth errors list. No holistic match found for error description."}, {"cause_line_score": 1, "effect_line_score": 0, "error_type_score": 0, "error_message_score": 0.0, "error_message_eval_reason": "The cause line exactly matches the cause line of Ground Truth Error 2. However, the effect line in the LLM Output does not match the effect line of Ground Truth Error 2. Additionally, the error message and type in the LLM Output ('TypeError: 'numpy.ndarray' object is not callable') match the error message and type of Ground Truth Error 2, but as the effect line did not match, a holistic match was not achieved. Therefore, the error message is completely irrelevant to the specific error instance matching the cause line and gets a score of 0.0."}]]}
{"id": 29, "eval_result": [[{"cause_line_score": 0, "effect_line_score": 0, "error_type_score": 0, "error_message_score": 0.0, "error_message_eval_reason": "No holistic match found with any error instance in Ground Truth Errors list."}, {"cause_line_score": 1, "effect_line_score": 1, "error_type_score": 0, "error_message_score": 0.0, "error_message_eval_reason": "The cause and effect lines holistically matched Ground Truth Error 2 perfectly. However, the error type and error message were completely different and irrelevant. The Ground Truth Error 2 indicated 'matplotlib.units.ConversionError: Failed to convert value(s) to axis units: ['3', '10']', whereas the LLM Output Error had 'ValueError: Too many values to unpack (expected 2)'. Hence, the error type and error message scores are both 0."}]]}
{"id": 30, "eval_result": [[{"cause_line_score": 0, "effect_line_score": 0, "error_type_score": 0, "error_message_score": 0.0, "error_message_eval_reason": "No holistic match found with any error instance in Ground Truth Errors list."}]]}
{"id": 31, "eval_result": [[{"cause_line_score": 0, "effect_line_score": 0, "error_type_score": 0, "error_message_score": 0.0, "error_message_eval_reason": "No holistic match found with any error instance in Ground Truth Errors list."}, {"cause_line_score": 1, "effect_line_score": 1, "error_type_score": 0, "error_message_score": 0.0, "error_message_eval_reason": "Cause and Effect lines matched Ground Truth Error 1 perfectly. However, the error type and message were completely different from Ground Truth Error 1 and 2. Thus, no holistic match found."}]]}
{"id": 32, "eval_result": [[{"cause_line_score": 0, "effect_line_score": 0, "error_type_score": 0, "error_message_score": 0.0, "error_message_eval_reason": "No holistic match found with any error instance in Ground Truth Errors list. The LLM Output has 'plt.xlabel(z-axis)  # Modified line with error' as both cause and effect lines and an error message 'NameError: name 'z-axis' is not defined'. However, the closest Ground Truth Error only matches on the cause and effect lines but contains a different error message 'NameError: name 'axis' is not defined'. Additionally, other errors do not share any similarities with the LLM Output."}, {"cause_line_score": 1, "effect_line_score": 1, "error_type_score": 0, "error_message_score": 0.0, "error_message_eval_reason": "The LLM's detected error matches the cause and effect lines of Ground Truth Error 2 perfectly. However, the error message and error type do not match. The error message in the LLM output is 'ValueError: The number of tick labels does not match the number of ticks' rather than 'matplotlib.units.ConversionError: Failed to convert value(s) to axis units: ['3', '10']'. Therefore, there is no holistic match with any specific error instance in the Ground Truth Errors list."}]]}
{"id": 33, "eval_result": [[{"cause_line_score": 0, "effect_line_score": 0, "error_type_score": 0, "error_message_score": 0.0, "error_message_eval_reason": "No holistic match found with any error instance in Ground Truth Errors list."}, {"cause_line_score": 0, "effect_line_score": 0, "error_type_score": 0, "error_message_score": 0.0, "error_message_eval_reason": "No holistic match found with any error instance in Ground Truth Errors list. The LLM's output error describes an issue with swapped x and y coordinates and incorrect formatting of coordinates, which does not correspond to any NameError described in the ground truth."}]]}
{"id": 34, "eval_result": [[{"cause_line_score": 0, "effect_line_score": 0, "error_type_score": 0, "error_message_score": 0.0, "error_message_eval_reason": "No holistic match found with any error instance in Ground Truth Errors list."}, {"cause_line_score": 0, "effect_line_score": 0, "error_type_score": 0, "error_message_score": 0.0, "error_message_eval_reason": "No holistic match found with any error instance in Ground Truth Errors list."}]]}
{"id": 35, "eval_result": [[{"cause_line_score": 1, "effect_line_score": 0, "error_type_score": 0, "error_message_score": 0.0, "error_message_eval_reason": "The LLM output cause line matched exactly with the cause line of Ground Truth Error 1. However, the effect line, error type, and error message did not match at all with the same error instance (Ground Truth Error 1), nor did they match with any of the other ground truth errors holistically."}, {"cause_line_score": 1, "effect_line_score": 0, "error_type_score": 0, "error_message_score": 0.0, "error_message_eval_reason": "No holistic match found with any error instance in Ground Truth Errors list."}]]}
{"id": 36, "eval_result": [[{"cause_line_score": 0, "effect_line_score": 0, "error_type_score": 0, "error_message_score": 0.0, "error_message_eval_reason": "No holistic match found with any error instance in Ground Truth Errors list."}, {"cause_line_score": 0, "effect_line_score": 0, "error_type_score": 0, "error_message_score": 0.0, "error_message_eval_reason": "No holistic match found with any error instance in Ground Truth Errors list."}]]}
{"id": 37, "eval_result": [[{"cause_line_score": 0, "effect_line_score": 0, "error_type_score": 0, "error_message_score": 0.0, "error_message_eval_reason": "No holistic match found with any error instance in Ground Truth Errors list. The cause line, effect line, error message, and error type in the LLM Output do not correspond to any specific error instance described in the Ground Truth."}, {"cause_line_score": 1, "effect_line_score": 0, "error_type_score": 0, "error_message_score": 0.0, "error_message_eval_reason": "Cause line matched Ground Truth Error 3, but effect line, error type, and error message did not match any specifics of Ground Truth Error 3 or any other error instance in the Ground Truth Errors list. Specifically, the effect line 'plt.show()' was not mentioned in Ground Truth, and the error message 'ValueError: bottom cannot be larger than top' does not match 'NameError: name 'matplotlab' is not defined. Did you mean: 'matplotlib'?'"}]]}
{"id": 38, "eval_result": [[{"cause_line_score": 0, "effect_line_score": 0, "error_type_score": 0, "error_message_score": 0.0, "error_message_eval_reason": "No holistic match found with any error instance in Ground Truth Errors list."}, {"cause_line_score": 1, "effect_line_score": 0, "error_type_score": 0, "error_message_score": 0.0, "error_message_eval_reason": "The LLM's output did partially match Ground Truth Error 2's cause line ('plt.subplots_adjust(left=0.2, bottom=-0.3)'). However, the LLM's effect line ('plt.show()') did not match Ground Truth Error 2's effect line ('matplotlab.use('tkagg')'). Additionally, the error message and error type did not correspond at all to Ground Truth Error 2 (or any of the errors). The LLM identified a 'UserWarning', whereas both Ground Truth Error 1 and Ground Truth Error 2 were 'TypeError' and 'NameError', respectively. Finally, the error message 'UserWarning: Tight layout not applied. The figure layout has 'tight' set but the figure size is too small to apply it effectively.' is completely irrelevant to both Ground Truth Error 1 and Ground Truth Error 2."}]]}
{"id": 39, "eval_result": [[{"cause_line_score": 0, "effect_line_score": 0, "error_type_score": 0, "error_message_score": 0.0, "error_message_eval_reason": "No holistic match found with any error instance in Ground Truth Errors list. The cause and effect lines, error types, and error messages in the LLM Output Error do not match any specific error instance from the Ground Truth Errors. Specifically, the cause line 'matplotlib.use('Agg')' and effect line 'matplotlib.use('tkagg')' are not present in any of the ground truth error dictionaries, and the error message about backend conflict does not correspond to the TypeError messages in the ground truth errors."}, {"cause_line_score": 0, "effect_line_score": 0, "error_type_score": 0, "error_message_score": 0.0, "error_message_eval_reason": "No holistic match found with any error instance in Ground Truth Errors list."}]]}
{"id": 40, "eval_result": [[{"cause_line_score": 0, "effect_line_score": 0, "error_type_score": 0, "error_message_score": 0.0, "error_message_eval_reason": "No holistic match found with any error instance in Ground Truth Errors list. The LLM output's cause line (matplotlib.use('tkagg')) does not match with any cause lines in the Ground Truth Errors. Therefore, no further comparisons can be made for effect lines, error type, or error message."}, {"cause_line_score": 1, "effect_line_score": 0, "error_type_score": 0, "error_message_score": 0.0, "error_message_eval_reason": "The LLM Output Error's cause line ('plt.subplots_adjust(left=0.2, bottom=-0.3)') matches the cause line in Ground Truth Error 2. However, the effect line ('plt.show()') does not match the effect line in Ground Truth Error 2 ('matplotlab.use('tkagg')'). The error type is 'TypeError' in the Ground Truth Error 2, whereas the LLM Output Error has 'ValueError'. Additionally, the error description ('ValueError: 'bottom' cannot be negative') is completely unrelated to the Ground Truth Error 2's error message ('NameError: name 'matplotlab' is not defined. Did you mean: 'matplotlib'?')."}]]}
{"id": 41, "eval_result": [[{"cause_line_score": 0, "effect_line_score": 0, "error_type_score": 0, "error_message_score": 0.0, "error_message_eval_reason": "No holistic match found with any error instance in Ground Truth Errors list."}, {"cause_line_score": 0, "effect_line_score": 0, "error_type_score": 0, "error_message_score": 0.0, "error_message_eval_reason": "No holistic match found with any error instance in Ground Truth Errors list."}]]}
{"id": 42, "eval_result": [[{"cause_line_score": 0, "effect_line_score": 0, "error_type_score": 0, "error_message_score": 0.0, "error_message_eval_reason": "No holistic match found with any error instance in Ground Truth Errors list. The cause line, effect line, and error message of the LLM Output Error do not correspond to any single specific error instance in the Ground Truth Errors list."}, {"cause_line_score": 0, "effect_line_score": 0, "error_type_score": 0, "error_message_score": 0.0, "error_message_eval_reason": "No holistic match found with any error instance in Ground Truth Errors list."}]]}
{"id": 43, "eval_result": [[{"cause_line_score": 0, "effect_line_score": 0, "error_type_score": 0, "error_message_score": 0.0, "error_message_eval_reason": "No holistic match found with any error instance in Ground Truth Errors list. The cause line 'x = pd.Series(range(30)).values  # Introduced error here' in the LLM Output does not exactly match any cause line from the Ground Truth Errors. Additionally, the effect line 'ax.bar(x, z_values[:, y], zs=y, zdir='y', color=color, alpha=0.8)' and error type 'NameError' from the LLM Output do not correspond to the same specific error instance as any complete error in Ground Truth Errors."}, {"cause_line_score": 0, "effect_line_score": 0, "error_type_score": 0, "error_message_score": 0.0, "error_message_eval_reason": "No holistic match found with any error instance in Ground Truth Errors list."}]]}
{"id": 44, "eval_result": [[{"cause_line_score": 0, "effect_line_score": 0, "error_type_score": 0, "error_message_score": 0.0, "error_message_eval_reason": "No holistic match found with any error instance in Ground Truth Errors list."}, {"cause_line_score": 1, "effect_line_score": 0, "error_type_score": 0, "error_message_score": 0.0, "error_message_eval_reason": "No holistic match found with any error instance in Ground Truth Errors list. Cause line matched Ground Truth Error 1, but effect line, error type, and error message did not align."}]]}
{"id": 45, "eval_result": [[{"cause_line_score": 1, "effect_line_score": 0, "error_type_score": 0, "error_message_score": 0.0, "error_message_eval_reason": "The LLM's output 'cause_line' exactly matches the 'cause_error_line' of Ground Truth Error 1. However, the 'effect_line' and 'error_message' do not match either of the Ground Truth Errors in the list. Specifically, the 'effect_line' provided in the LLM output does not appear as the 'effect_error_line' of the same error instance in the Ground Truth. Furthermore, the 'error_message' does not correspond to the error message of either error instance."}, {"cause_line_score": 0, "effect_line_score": 0, "error_type_score": 0, "error_message_score": 0.0, "error_message_eval_reason": "No holistic match found with any error instance in Ground Truth Errors list."}]]}
{"id": 46, "eval_result": [[{"cause_line_score": 0, "effect_line_score": 0, "error_type_score": 0, "error_message_score": 0.0, "error_message_eval_reason": "No holistic match found with any error instance in Ground Truth Errors list."}, {"cause_line_score": 1, "effect_line_score": 0, "error_type_score": 0, "error_message_score": 0.0, "error_message_eval_reason": "No holistic match found with any error instance in Ground Truth Errors list."}]]}
{"id": 47, "eval_result": [[{"cause_line_score": 1, "effect_line_score": 0, "error_type_score": 0, "error_message_score": 0.0, "error_message_eval_reason": "No holistic match found with any error instance in Ground Truth Errors list."}, {"cause_line_score": 0, "effect_line_score": 0, "error_type_score": 0, "error_message_score": 0.0, "error_message_eval_reason": "No holistic match found with any error instance in Ground Truth Errors list."}]]}
