{"id": 1, "eval_result": [[{"cause_line_score": 0, "effect_line_score": 0, "error_type_score": 0, "error_message_score": 0.0, "error_message_eval_reason": "No holistic match found with any error instance in Ground Truth Errors list. The LLM detected error involves a different cause line, effect line, and error type ('Redundant backend setting') not present in any of the Ground Truth Errors, which focus on value and unpacking issues."}, {"cause_line_score": 1, "effect_line_score": 1, "error_type_score": 1, "error_message_score": 1.0, "error_message_eval_reason": "Holistically matched Ground Truth Error 1 perfectly."}, {"cause_line_score": 0, "effect_line_score": 0, "error_type_score": 0, "error_message_score": 0.0, "error_message_eval_reason": "No holistic match found with any error instance in Ground Truth Errors list. The cause line, effect line, and error type in the LLM Output do not exactly match any specific error instance in the provided ground_truth_errors list. Additionally, the error messages describe different issues: the LLM Output error message specifies a 'TypeError: whis must be a float or a pair of floats' while the Ground Truth errors specify 'ValueError: not enough values to unpack (expected 2, got 1)' and 'ValueError: X must have 2 or fewer dimensions'."}]]}
{"id": 2, "eval_result": [[{"cause_line_score": 0, "effect_line_score": 0, "error_type_score": 0, "error_message_score": 0.0, "error_message_eval_reason": "No holistic match found with any error instance in Ground Truth Errors list. The LLM's identified issue with 'matplotlib.use('agg')' being unnecessary does not correspond to any specific error instances in the Ground Truth Errors, which relate to specific ValueErrors and TypeErrors. The LLM's error message about redundancy does not align with the provided ValueError and TypeError messages."}, {"cause_line_score": 1, "effect_line_score": 1, "error_type_score": 0, "error_message_score": 0.75, "error_message_eval_reason": "Cause line and effect line exactly match Ground Truth Error 1. However, the error type described in LLM's output ('ValueError') does not exactly match the error message in Ground Truth Error 1 ('ValueError: X must have 2 or fewer dimensions'). The error message in LLM's output is mostly correct but has slight variations ('ValueError: Input data shape is not as expected for a boxplot.'). No holistic match found with any other error instance in Ground Truth Errors list."}, {"cause_line_score": 0, "effect_line_score": 0, "error_type_score": 0, "error_message_score": 0.0, "error_message_eval_reason": "No holistic match found with any error instance in Ground Truth Errors list."}]]}
{"id": 3, "eval_result": [[{"cause_line_score": 0, "effect_line_score": 0, "error_type_score": 0, "error_message_score": 0.0, "error_message_eval_reason": "No holistic match found with any error instance in Ground Truth Errors list. The LLM detected a redundancy issue with 'matplotlib.use('agg')' which does not correspond to any of the specific errors in the ground truth list. Ground Truth Errors list includes 'ValueError' and 'TypeError' with specific error messages related to data reshaping, whis parameter, and dpi settings, none of which align with the LLM's reported redundancy."}, {"cause_line_score": 1, "effect_line_score": 1, "error_type_score": 1, "error_message_score": 0.75, "error_message_eval_reason": "Holistically matched Ground Truth Error 1 but with a slight variation in capitalization in the error message."}, {"cause_line_score": 1, "effect_line_score": 1, "error_type_score": 0, "error_message_score": 0.0, "error_message_eval_reason": "The cause line and effect line from the LLM's output exactly match those of Ground Truth Error 2, so both scores are 1. However, the error type in the LLM's output ('TypeError') does not match the error type in Ground Truth Error 2 ('ValueError'), resulting in a score of 0 for the error type. Furthermore, the error message in the LLM's output is 'TypeError: 'whis' must be a float or a pair of percentiles' which is completely irrelevant compared to the error message in Ground Truth Error 2 ('ValueError: not enough values to unpack (expected 2, got 1)'), hence a score of 0.0 for the error message."}]]}
{"id": 4, "eval_result": [[{"cause_line_score": 1, "effect_line_score": 1, "error_type_score": 1, "error_message_score": 0.75, "error_message_eval_reason": "Ground Truth Error 1 had a detailed error message ('NameError: name 'pd' is not defined. Did you mean: 'id'?') compared to the LLM's output ('NameError: name 'pd' is not defined'). The critical part of the message matches, but the detailed suggestion was missing in the LLM's output, hence a score of 0.75."}, {"cause_line_score": 1, "effect_line_score": 0, "error_type_score": 0, "error_message_score": 0.0, "error_message_eval_reason": "No holistic match found with any error instance in Ground Truth Errors list. The cause line 'w = pd.Series(np.linspace(-10, 10, 400))' matches with Ground Truth Error 1's cause line. However, the effect line 'axs[1, 1].plot(z**2, w**2, 'brown')' does not match with any effect_line in the Ground Truth Errors. Additionally, the error message 'TypeError or ValueError due to incompatible operations' does not align with any specific error message in the Ground Truth Errors. Due to these mismatched elements, a holistic match is not achieved."}, {"cause_line_score": 0, "effect_line_score": 0, "error_type_score": 0, "error_message_score": 0.0, "error_message_eval_reason": "No holistic match found with any error instance in Ground Truth Errors list."}, {"cause_line_score": 0, "effect_line_score": 0, "error_type_score": 0, "error_message_score": 0.0, "error_message_eval_reason": "No holistic match found with any error instance in Ground Truth Errors list."}]]}
{"id": 5, "eval_result": [[{"cause_line_score": 1, "effect_line_score": 1, "error_type_score": 1, "error_message_score": 0.75, "error_message_eval_reason": "Cause and Effect lines and Error Type matched Ground Truth Error 2, but error message was mostly correct with slight variations - hence 0.75 score."}, {"cause_line_score": 1, "effect_line_score": 1, "error_type_score": 1, "error_message_score": 1.0, "error_message_eval_reason": "The LLM's detected error holistically matches Ground Truth Error 1 perfectly. The cause line ('axs[0, 0].plot(z, w, 'r')'), effect line ('axs[0, 0].plot(z, w, 'r')'), and error message ('ValueError: x and y must have same first dimension, but have shapes (50,) and (400,)') exactly match the corresponding fields in Ground Truth Error 1."}, {"cause_line_score": 0, "effect_line_score": 0, "error_type_score": 0, "error_message_score": 0.0, "error_message_eval_reason": "No holistic match found with any error instance in Ground Truth Errors list. The cause and effect lines as well as the error message and type from the LLM output do not correspond with any specific error instance described in the Ground Truth Errors."}]]}
{"id": 6, "eval_result": [[{"cause_line_score": 1, "effect_line_score": 1, "error_type_score": 1, "error_message_score": 1.0, "error_message_eval_reason": "Holistically matched Ground Truth Error 2 perfectly."}, {"cause_line_score": 1, "effect_line_score": 1, "error_type_score": 1, "error_message_score": 1.0, "error_message_eval_reason": "Holistically matched Ground Truth Error 1 perfectly."}, {"cause_line_score": 0, "effect_line_score": 0, "error_type_score": 0, "error_message_score": 0.0, "error_message_eval_reason": "No holistic match found with any error instance in Ground Truth Errors list."}]]}
{"id": 7, "eval_result": [[{"cause_line_score": 0, "effect_line_score": 0, "error_type_score": 0, "error_message_score": 0.0, "error_message_eval_reason": "No holistic match found with any error instance in Ground Truth Errors list. The LLM Output Error describes a 'Redundant backend setting' which does not correlate with any of the ground truth errors (either 'ValueError' related to dimension mismatch or 'NameError' related to incorrect module name)."}, {"cause_line_score": 1, "effect_line_score": 1, "error_type_score": 1, "error_message_score": 1.0, "error_message_eval_reason": "Holistically matched Ground Truth Error 1 perfectly."}, {"cause_line_score": 0, "effect_line_score": 0, "error_type_score": 0, "error_message_score": 0.0, "error_message_eval_reason": "No holistic match found with any error instance in Ground Truth Errors list."}, {"cause_line_score": 0, "effect_line_score": 0, "error_type_score": 0, "error_message_score": 0.0, "error_message_eval_reason": "No holistic match found with any error instance in Ground Truth Errors list."}]]}
{"id": 8, "eval_result": [[{"cause_line_score": 1, "effect_line_score": 1, "error_type_score": 0, "error_message_score": 0.0, "error_message_eval_reason": "No holistic match found with any error instance in Ground Truth Errors list. The cause and effect lines matched with Ground Truth Error 1 and 2, but the error type and error message are completely different ('TypeError: 'DataFrame' object cannot be interpreted as an integer' vs. 'NameError: name 'pd' is not defined. Did you mean: 'd'?')."}, {"cause_line_score": 0, "effect_line_score": 0, "error_type_score": 0, "error_message_score": 0.0, "error_message_eval_reason": "No holistic match found with any error instance in Ground Truth Errors list."}, {"cause_line_score": 0, "effect_line_score": 0, "error_type_score": 0, "error_message_score": 0.0, "error_message_eval_reason": "No holistic match found with any error instance in Ground Truth Errors list. The cause line 'plt.show()' and effect line 'plt.show()' do not match any cause or effect lines in the ground truth errors. Additionally, the error type and message regarding a non-interactive environment do not align with the 'NameError: name 'pd' is not defined.' errors in the ground truth."}]]}
{"id": 9, "eval_result": [[{"cause_line_score": 0, "effect_line_score": 0, "error_type_score": 0, "error_message_score": 0.0, "error_message_eval_reason": "No holistic match found with any error instance in Ground Truth Errors list."}, {"cause_line_score": 1, "effect_line_score": 0, "error_type_score": 0, "error_message_score": 0.0, "error_message_eval_reason": "The LLM Output Error cause line 'q1, median, q3 = np.percentile(d, [75, 50, 25])' matches Ground Truth Error 1's cause line perfectly. However, the effect line 'axes[0].scatter(i + 1, median, color='red', zorder=3)' does not match any effect line in the Ground Truth errors. Similarly, the error type 'Incorrect calculation of quartiles and median' does not match the error types of either Ground Truth errors. Therefore, the error message 'Incorrect calculation of quartiles and median' is irrelevant and incorrect compared to the error messages in the Ground Truth errors."}, {"cause_line_score": 1, "effect_line_score": 1, "error_type_score": 1, "error_message_score": 0.25, "error_message_eval_reason": "Holistically matched Ground Truth Error 2. The cause and effect lines, as well as the error type, exactly matched that of Ground Truth Error 2. However, the error message in the LLM output ('NameError: name 'pd' is not defined') is only loosely related to the error message in Ground Truth Error 2 ('NameError: name 'pd' is not defined. Did you mean: 'd'?'). The LLM output did not include the additional detail 'Did you mean: 'd'?', hence a score of 0.25."}]]}
{"id": 10, "eval_result": [[{"cause_line_score": 1, "effect_line_score": 1, "error_type_score": 1, "error_message_score": 1.0, "error_message_eval_reason": "Holistically matched Ground Truth Error 1 perfectly. The cause line, effect line, and error message in the LLM Output are exactly the same as those in Ground Truth Error 1. Even the error message matches exactly, including the phrasing."}, {"cause_line_score": 1, "effect_line_score": 0, "error_type_score": 0, "error_message_score": 0.0, "error_message_eval_reason": "The LLM Output's cause line matches exactly with Ground Truth Error 2's cause line ('q1, median, q3 = np.percentile(d, [75, 50, 25])'). However, the effect line in the LLM Output ('axes[0].vlines(i + 1, whiskers[0], whiskers[1], color='k', linestyle='-')') does not match the effect line in Ground Truth Error 2 ('whiskers = [np.min(d[d >= q1 - 1.5 * (q3 - q1)]), np.max(d[d <= q3 + 1.5 * (q3 - q1)])]'). Consequently, the error type and error message do not match either. The error message related to quartile and median values is a logic error and does not relate to the ValueError indicated in the ground truth. No holistic match found with any error instance in Ground Truth Errors list."}, {"cause_line_score": 0, "effect_line_score": 0, "error_type_score": 0, "error_message_score": 0.0, "error_message_eval_reason": "No holistic match found with any error instance in Ground Truth Errors list."}]]}
{"id": 101, "eval_result": [[{"cause_line_score": 0, "effect_line_score": 0, "error_type_score": 0, "error_message_score": 0.0, "error_message_eval_reason": "No holistic match found with any error instance in Ground Truth Errors list."}, {"cause_line_score": 1, "effect_line_score": 1, "error_type_score": 0, "error_message_score": 0.75, "error_message_eval_reason": "The LLM's error analysis was holistically compared to Ground Truth Error 1. The cause line exactly matched ('fig, axs = plt.subplots(2, 2.0, figsize=(10, 8))'), resulting in a score of 1. The effect line also exactly matched ('fig, axs = plt.subplots(2, 2.0, figsize=(10, 8))'), resulting in a score of 1. However, the error type did not match, leading to a score of 0. The LLM's error message ('TypeError: 'float' object cannot be interpreted as an integer') is mostly correct but describes a slightly different error compared to the ground truth ('ValueError: Number of columns must be a positive integer, not 2.0'), hence the score is 0.75."}, {"cause_line_score": 1, "effect_line_score": 1, "error_type_score": 1, "error_message_score": 1.0, "error_message_eval_reason": "Holistically matched Ground Truth Error 2 perfectly."}]]}
{"id": 102, "eval_result": [[{"cause_line_score": 1, "effect_line_score": 1, "error_type_score": 0, "error_message_score": 0.75, "error_message_eval_reason": "The LLM Output Error matches Ground Truth Error 2 perfectly in terms of cause and effect lines. However, the error type ('TypeError' vs 'ValueError') does not match. The errors both involve misuse of float instead of integer, which is the context of the LLM's error message. Given that, the error message is mostly correct, hence a score of 0.75."}, {"cause_line_score": 1, "effect_line_score": 1, "error_type_score": 1, "error_message_score": 1.0, "error_message_eval_reason": "Holistically matched Ground Truth Error 3 perfectly. The cause line, effect line, error type, and error message are exactly the same."}, {"cause_line_score": 1, "effect_line_score": 1, "error_type_score": 1, "error_message_score": 1.0, "error_message_eval_reason": "Holistically matched Ground Truth Error 4 perfectly."}]]}
{"id": 103, "eval_result": []}
{"id": 104, "eval_result": [[{"cause_line_score": 1, "effect_line_score": 1, "error_type_score": 0, "error_message_score": 0.0, "error_message_eval_reason": "The LLM's detected error cause line and effect line exactly match Ground Truth Error 2. However, the error type and error message do not match. The Ground Truth Error 2 has a ValueError with the message 'Number of columns must be a positive integer, not 2.0', whereas the LLM output has a TypeError with the message 'TypeError: 'float' object cannot be interpreted as an integer'. Since the error type and error message do not match, the evaluation scores are 0 for both the error type and error message."}, {"cause_line_score": 1, "effect_line_score": 1, "error_type_score": 1, "error_message_score": 1.0, "error_message_eval_reason": "Holistically matched Ground Truth Error 3 perfectly."}, {"cause_line_score": 1, "effect_line_score": 1, "error_type_score": 1, "error_message_score": 1.0, "error_message_eval_reason": "Holistically matched Ground Truth Error 1 perfectly."}]]}
{"id": 105, "eval_result": [[{"cause_line_score": 1, "effect_line_score": 1, "error_type_score": 1, "error_message_score": 1.0, "error_message_eval_reason": "Holistically matched Ground Truth Error 1 perfectly."}, {"cause_line_score": 1, "effect_line_score": 0, "error_type_score": 1, "error_message_score": 0.75, "error_message_eval_reason": "Cause and Error Type matched Ground Truth Error 2, but effect line did not match and the error message lacked minor detail."}, {"cause_line_score": 1, "effect_line_score": 1, "error_type_score": 1, "error_message_score": 1.0, "error_message_eval_reason": "Holistically matched Ground Truth Error 3 perfectly. The cause line, effect line, error type, and error message from the LLM's output exactly match with Ground Truth Error 3 ('cause_error_line': \"plt.savefig('novice_final.png', dpi=0)\", 'effect_error_line': \"plt.savefig('novice_final.png', dpi=0)  # Error: invalid DPI setting\", 'error_message': 'ValueError: dpi must be positive')."}]]}
{"id": 106, "eval_result": [[{"cause_line_score": 0, "effect_line_score": 0, "error_type_score": 0, "error_message_score": 0.0, "error_message_eval_reason": "No holistic match found with any error instance in Ground Truth Errors list. The error identified by the LLM ('matplotlib.use('tkagg')', 'No error message, but setting backend twice is not recommended.') does not align with any of the specific error instances provided in the Ground Truth. None of the cause lines, effect lines, error types, or error messages in the Ground Truth Errors correspond to the LLM's detected error."}, {"cause_line_score": 0, "effect_line_score": 0, "error_type_score": 0, "error_message_score": 0.0, "error_message_eval_reason": "No holistic match found with any error instance in Ground Truth Errors list."}, {"cause_line_score": 0, "effect_line_score": 0, "error_type_score": 0, "error_message_score": 0.0, "error_message_eval_reason": "No holistic match found with any error instance in Ground Truth Errors list."}, {"cause_line_score": 1, "effect_line_score": 1, "error_type_score": 1, "error_message_score": 0.75, "error_message_eval_reason": "Holistically matched Ground Truth Error 2. The cause line, effect line, and error type match perfectly with Ground Truth Error 2. The error message in the LLM Output is mostly correct but has a slight variation: the LLM Output includes an extra period at the end of the message ('to_rgba'.') which is not present in the Ground Truth ('to_rgba'). Hence, a 0.75 score is given for the error message."}]]}
{"id": 107, "eval_result": [[{"cause_line_score": 0, "effect_line_score": 0, "error_type_score": 0, "error_message_score": 0.0, "error_message_eval_reason": "No holistic match found with any error instance in Ground Truth Errors list. The cause line 'matplotlib.use('tkagg')' from the LLM Output is not present in any of the Ground Truth errors. Consequently, there is no basis for matching the effect lines or error types, and the error message about a 'UserWarning or RuntimeError due to backend conflict' does not correspond to the specific error messages in the Ground Truth errors."}, {"cause_line_score": 0, "effect_line_score": 0, "error_type_score": 0, "error_message_score": 0.0, "error_message_eval_reason": "No holistic match found with any error instance in Ground Truth Errors list."}, {"cause_line_score": 0, "effect_line_score": 0, "error_type_score": 0, "error_message_score": 0.0, "error_message_eval_reason": "No holistic match found with any error instance in Ground Truth Errors list. The cause and effect lines in the LLM Output do not match any cause or effect lines in the Ground Truth errors. Additionally, the error message 'Incorrect y-axis limits for Pressure' is completely irrelevant to the error messages listed in the Ground Truth errors, which involve different types of errors and root causes."}, {"cause_line_score": 0, "effect_line_score": 0, "error_type_score": 0, "error_message_score": 0.0, "error_message_eval_reason": "No holistic match found with any error instance in Ground Truth Errors list. The cause line, effect line, and error message from the LLM Output do not correspond to any specific error instance described in the Ground Truth Errors."}, {"cause_line_score": 1, "effect_line_score": 1, "error_type_score": 1, "error_message_score": 1.0, "error_message_eval_reason": "Holistically matched Ground Truth Error 3 perfectly."}]]}
{"id": 108, "eval_result": [[{"cause_line_score": 0, "effect_line_score": 0, "error_type_score": 0, "error_message_score": 0.0, "error_message_eval_reason": "No holistic match found with any error instance in Ground Truth Errors list. The cause line, effect line, and error message in the LLM Output Error do not correspond to any of the Ground Truth errors. Specifically, none of the Ground Truth errors involve 'matplotlib.use' or the RuntimeError related to changing the backend."}, {"cause_line_score": 0, "effect_line_score": 0, "error_type_score": 0, "error_message_score": 0.0, "error_message_eval_reason": "No holistic match found with any error instance in Ground Truth Errors list. The cause line and effect line in the LLM output ('p1, = host.plot([0, 1, 2], [0, 1, 2], label=\"Pressure\")') do not match any lines in the Ground Truth errors. The error message in the LLM output ('The plot will not match the specified points for \"Pressure\", \"Humidity\", and \"Wind Speed\".') is also completely different from the error messages in the Ground Truth errors, which are specific TypeError and ValueError messages."}, {"cause_line_score": 0, "effect_line_score": 0, "error_type_score": 0, "error_message_score": 0.0, "error_message_eval_reason": "No holistic match found with any error instance in Ground Truth Errors list."}, {"cause_line_score": 0, "effect_line_score": 0, "error_type_score": 0, "error_message_score": 0.0, "error_message_eval_reason": "No holistic match found with any error instance in Ground Truth Errors list."}]]}
{"id": 109, "eval_result": [[{"cause_line_score": 0, "effect_line_score": 0, "error_type_score": 0, "error_message_score": 0.0, "error_message_eval_reason": "No holistic match found with any error instance in Ground Truth Errors list. The cause line, effect line, and error type in the LLM output do not correspond to any of the Ground Truth error instances."}, {"cause_line_score": 0, "effect_line_score": 0, "error_type_score": 0, "error_message_score": 0.0, "error_message_eval_reason": "No holistic match found with any error instance in Ground Truth Errors list."}, {"cause_line_score": 0, "effect_line_score": 0, "error_type_score": 0, "error_message_score": 0.0, "error_message_eval_reason": "No holistic match found with any error instance in Ground Truth Errors list. The LLM's output error analysis does not correspond to any specific error instance given in the Ground Truth. The cause line, effect line, and error type are all different from those listed in the Ground Truth Errors, and the error message is not relevant to either of the provided Ground Truth error messages."}, {"cause_line_score": 0, "effect_line_score": 0, "error_type_score": 0, "error_message_score": 0.0, "error_message_eval_reason": "No holistic match found with any error instance in Ground Truth Errors list."}]]}
{"id": 110, "eval_result": [[{"cause_line_score": 0, "effect_line_score": 0, "error_type_score": 0, "error_message_score": 0.0, "error_message_eval_reason": "No holistic match found with any error instance in Ground Truth Errors list."}, {"cause_line_score": 0, "effect_line_score": 0, "error_type_score": 0, "error_message_score": 0.0, "error_message_eval_reason": "No holistic match found with any error instance in Ground Truth Errors list."}, {"cause_line_score": 0, "effect_line_score": 0, "error_type_score": 0, "error_message_score": 0.0, "error_message_eval_reason": "No holistic match found with any error instance in Ground Truth Errors list."}, {"cause_line_score": 1, "effect_line_score": 1, "error_type_score": 1, "error_message_score": 1.0, "error_message_eval_reason": "Holistically matched Ground Truth Error 3 perfectly."}]]}
{"id": 201, "eval_result": []}
{"id": 202, "eval_result": [[{"cause_line_score": 0, "effect_line_score": 0, "error_type_score": 0, "error_message_score": 0.0, "error_message_eval_reason": "No holistic match found with any error instance in Ground Truth Errors list. The LLM's detected error with a cause line 'matplotlib.use('tkagg')' and effect line 'matplotlib.use('tkagg')' pertains to a logical inconsistency about backend setting, which is entirely different from the Ground Truth errors provided, all of which involve AttributeError or ValueError in the context of handling numpy arrays and matplotlib objects. Therefore, neither the cause/effect lines nor the error messages/types match any Ground Truth error instance."}, {"cause_line_score": 0, "effect_line_score": 0, "error_type_score": 0, "error_message_score": 0.0, "error_message_eval_reason": "No holistic match found with any error instance in Ground Truth Errors list. The LLM's detected error and the provided Ground Truth Errors are fundamentally different in terms of error type: LLM detected an 'IndentationError', whereas Ground Truth Errors contain 'AttributeError' and 'ValueError'. Furthermore, the cause and effect lines do not correspond to any specific instance in the Ground Truth errors."}, {"cause_line_score": 0, "effect_line_score": 0, "error_type_score": 0, "error_message_score": 0.0, "error_message_eval_reason": "No holistic match found with any error instance in Ground Truth Errors list. The LLM Output Error's cause line, effect line, and error type do not match any specific error instance in the provided Ground Truth Errors. The error message indicating a 'Logical error: plot does not meet color requirements' is entirely different from the attribute errors and value errors described in the Ground Truth Errors."}, {"cause_line_score": 1, "effect_line_score": 1, "error_type_score": 0, "error_message_score": 0.5, "error_message_eval_reason": "Cause line and effect line perfectly matched Ground Truth Error 3. However, the error type does not match; Ground Truth Error 3 specifies a 'ValueError' while the LLM output mentions a 'Logical error'. The error description partially matched since it identifies an incorrect structure in the boxplot data, but it is not specifically mentioning the dimensional constraint as in the Ground Truth Error 3."}, {"cause_line_score": 0, "effect_line_score": 0, "error_type_score": 0, "error_message_score": 0.0, "error_message_eval_reason": "No holistic match found with any error instance in Ground Truth Errors list. The LLM output error describes a logical error related to unnecessary subplots creation, which is not present among the Ground Truth errors. All Ground Truth errors involved incorrect usage of numpy functions or incorrect object references, leading to AttributeError or ValueError."}]]}
{"id": 203, "eval_result": [[{"cause_line_score": 0, "effect_line_score": 0, "error_type_score": 0, "error_message_score": 0.0, "error_message_eval_reason": "No holistic match found with any error instance in Ground Truth Errors list. The LLM's detected error concerning 'matplotlib.use('tkagg')' and logical inconsistency of setting backend multiple times does not align with any specific Ground Truth error instance (either in terms of cause line, effect line, error type, or error message). All Ground Truth errors involve explicit error messages and code causes relating to data handling and plotting inconsistencies, unlike the logical inconsistency stated in the LLM's output."}, {"cause_line_score": 1, "effect_line_score": 0, "error_type_score": 0, "error_message_score": 0.0, "error_message_eval_reason": "The 'cause_line' in the LLM Output exactly matches the 'cause_error_line' in Ground Truth Error 1. However, the 'effect_line', 'error_type' and 'error_message' do not match any of the Ground Truth Errors holistically."}, {"cause_line_score": 1, "effect_line_score": 1, "error_type_score": 1, "error_message_score": 1.0, "error_message_eval_reason": "Holistically matched Ground Truth Error 3 perfectly."}, {"cause_line_score": 0, "effect_line_score": 0, "error_type_score": 0, "error_message_score": 0.0, "error_message_eval_reason": "No holistic match found with any error instance in Ground Truth Errors list."}]]}
{"id": 204, "eval_result": [[{"cause_line_score": 1, "effect_line_score": 1, "error_type_score": 0, "error_message_score": 0.0, "error_message_eval_reason": "The LLM Output Error has an exact match in the cause line and effect line with Ground Truth Error 1. However, the error type described in the LLM Output Error ('Logical error: Imputer applied to wrong variable') does not match the error type in Ground Truth Error 1 ('ValueError: Input y contains NaN.'). Consequently, the error message is also completely different and irrelevant compared to the error message in Ground Truth Error 1. Therefore, no holistic match found with any error instance in Ground Truth Errors list."}, {"cause_line_score": 1, "effect_line_score": 0, "error_type_score": 0, "error_message_score": 0.0, "error_message_eval_reason": "No holistic match found with any error instance in Ground Truth Errors list. The cause line 'y_pred = model.predict(X_train)' matches the cause line of Ground Truth Error 2, but the effect line 'mse = mean_squared_error(y_train, y_pred)' and the error message 'Logical error: Predictions made on training set' do not match any corresponding effect line or error message in the Ground Truth Errors. Moreover, the error type 'Logical error' does not align with any of the error types in the Ground Truth Errors list."}, {"cause_line_score": 1, "effect_line_score": 0, "error_type_score": 0, "error_message_score": 0.0, "error_message_eval_reason": "The cause line 'y_pred = model.predict(X_train)' from the LLM Output exactly matches the cause line of Ground Truth Error 2. However, the effect line, error type, and error message do not match. The effect line in the LLM Output is 'plt.scatter(y_test, y_pred, color='blue', alpha=0.5)', while in Ground Truth Error 2 it's 'mse = mean_squared_error(y_test, y_pred)'. The error type and error message also don't align; the LLM Output describes a logical error in visualization, whereas Ground Truth Error 2 involves a ValueError due to inconsistent sample sizes. Therefore, there is no holistic match."}]]}
{"id": 205, "eval_result": [[{"cause_line_score": 0, "effect_line_score": 0, "error_type_score": 0, "error_message_score": 0.75, "error_message_eval_reason": "No holistic match found with any error instance in Ground Truth Errors list. The LLM Output's cause line does not match any specific Ground Truth cause_line exactly. Additionally, the effect line in the LLM's output is different from any Ground Truth effect_line. However, the LLM error message logically described the incorrect prediction on training data instead of test data, which is consistent with the logic behind one of the Ground Truth errors. Therefore, the error message is mostly correct but does not provide the exact error message in the Ground Truth."}, {"cause_line_score": 1, "effect_line_score": 1, "error_type_score": 0, "error_message_score": 0.5, "error_message_eval_reason": "Cause and Effect lines matched Ground Truth Error 2. The error type did not match because the LLM described a 'logic error' rather than a 'ValueError'. The error message was partially correct as it recognized the logic issue of using training labels instead of test labels but did not mention the inconsistency in the sample numbers that led to the ValueError."}, {"cause_line_score": 0, "effect_line_score": 0, "error_type_score": 0, "error_message_score": 0.0, "error_message_eval_reason": "No holistic match found with any error instance in Ground Truth Errors list."}]]}
{"id": 206, "eval_result": [[{"cause_line_score": 1, "effect_line_score": 1, "error_type_score": 0, "error_message_score": 0.5, "error_message_eval_reason": "Cause and Effect lines matched Ground Truth Error 1 exactly. However, the error type is different: LLM Output Error suggests 'Incorrect imputation of missing values on target variable', while Ground Truth Error 1 indicates 'ValueError: Input y contains NaN.' due to a logical error in imputation. The message is partially correct as it relates to incorrect imputation of missing values, but it lacks specificity and does not match exactly - hence a score of 0.5."}, {"cause_line_score": 1, "effect_line_score": 1, "error_type_score": 1, "error_message_score": 0.75, "error_message_eval_reason": "Cause and Effect lines and Error Type matched Ground Truth Error 2 perfectly, but the error message was mostly correct, indicating mismatched datasets but missing specific details about the number of samples."}]]}
{"id": 207, "eval_result": [[{"cause_line_score": 1, "effect_line_score": 0, "error_type_score": 0, "error_message_score": 0.0, "error_message_eval_reason": "No holistic match found with any error instance in Ground Truth Errors list."}, {"cause_line_score": 1, "effect_line_score": 1, "error_type_score": 1, "error_message_score": 0.75, "error_message_eval_reason": "Cause and Effect lines and Error Type matched Ground Truth Error 2. The error message reflects the same mistake but uses different wording, thus a score of 0.75 is given."}]]}
{"id": 208, "eval_result": [[{"cause_line_score": 1, "effect_line_score": 1, "error_type_score": 0, "error_message_score": 0.25, "error_message_eval_reason": "The cause and effect lines matched Ground Truth Error 3 and 4. However, the error type was different, and the error message was only loosely related."}, {"cause_line_score": 1, "effect_line_score": 1, "error_type_score": 0, "error_message_score": 0.0, "error_message_eval_reason": "The LLM's output cause and effect lines match Ground Truth Error 4. However, the error type in the Ground Truth is 'ValueError: No axis named 1 for object type Series', while the LLM output has 'TypeError: DataFrame.mean() got an unexpected keyword argument 'axis'', making the error type and message completely incorrect. The error type and message do not holistically match any specific error instance in the Ground Truth list."}, {"cause_line_score": 0, "effect_line_score": 0, "error_type_score": 0, "error_message_score": 0.0, "error_message_eval_reason": "No holistic match found with any error instance in Ground Truth Errors list."}]]}
{"id": 209, "eval_result": [[{"cause_line_score": 0, "effect_line_score": 0, "error_type_score": 0, "error_message_score": 0.0, "error_message_eval_reason": "No holistic match found with any error instance in Ground Truth Errors list."}, {"cause_line_score": 1, "effect_line_score": 0, "error_type_score": 0, "error_message_score": 0.0, "error_message_eval_reason": "The LLM's cause line 'mean_region = df[['region_northeast', 'region_northwest', 'region_southeast', 'region_southwest']].mean().mean()' exactly matches the cause line of Ground Truth Error 2. However, the effect line does not match the effect line of any specific error instance in the Ground Truth Errors. Additionally, the error type ('KeyError') does not match exactly as the LLM points to 'Attempting to access non-existent columns due to drop_first=True,' which does not exactly match either Ground Truth Error's messages. Holistically, no error instance from the Ground Truth errors matches completely with the LLM's output."}, {"cause_line_score": 0, "effect_line_score": 0, "error_type_score": 0, "error_message_score": 0.0, "error_message_eval_reason": "No holistic match found with any error instance in Ground Truth Errors list."}]]}
{"id": 210, "eval_result": [[{"cause_line_score": 1, "effect_line_score": 1, "error_type_score": 0, "error_message_score": 0.0, "error_message_eval_reason": "Cause and effect lines matched Ground Truth Error 2, but error type and error message were completely different."}, {"cause_line_score": 1, "effect_line_score": 1, "error_type_score": 0, "error_message_score": 0.25, "error_message_eval_reason": "The cause and effect lines in the LLM output match the cause and effect lines in Ground Truth Error 3 exactly. However, the error type does not match. The LLM output reports a TypeError, while the Ground Truth reports a ValueError. The error message in the LLM output ('TypeError: 'axis' is an invalid keyword argument for this function') is only loosely related to the Ground Truth error message ('ValueError: No axis named 1 for object type Series'). The difference in error type and the specific message description resulted in a low score for the error message match."}, {"cause_line_score": 1, "effect_line_score": 1, "error_type_score": 0, "error_message_score": 0.0, "error_message_eval_reason": "The LLM Output error analysis cause line ('mean_children = df['children'].mean(axis=1)') and effect line ('mean_children = df['children'].mean(axis=1)') exactly match the cause and effect lines of Ground Truth Error 4. However, the error message in the LLM Output ('TypeError: 'axis' is an invalid keyword argument for this function') does not match the error message of Ground Truth Error 4 ('ValueError: No axis named 1 for object type Series'). The error type is also different ('TypeError' in LLM Output vs. 'ValueError' in Ground Truth Error 4). Consequently, the error message score is 0.0 due to being completely irrelevant, and the error type score is 0."}]]}
{"id": 301, "eval_result": [[{"cause_line_score": 1, "effect_line_score": 1, "error_type_score": 0, "error_message_score": 0.25, "error_message_eval_reason": "The cause and effect lines in the LLM Output exactly match those of Ground Truth Error 1. However, the error type does not match, as the LLM mentions poor performance instead of a ValueError. The error message in the LLM Output is only loosely related to the Ground Truth Error 1, as it mentions mismatched data but lacks specifics about inconsistent numbers of samples and gives a generalized statement about poor performance. Hence, a score of 0.25."}, {"cause_line_score": 1, "effect_line_score": 1, "error_type_score": 0, "error_message_score": 0.5, "error_message_eval_reason": "Cause and Effect lines matched perfectly with Ground Truth Error 2, but the LLM's error message was only a high-level description of the issue without the specific 'ValueError' and sample numbers."}]]}
{"id": 302, "eval_result": []}
{"id": 303, "eval_result": [[{"cause_line_score": 1, "effect_line_score": 1, "error_type_score": 0, "error_message_score": 0.5, "error_message_eval_reason": "Cause and effect lines match Ground Truth Error 1 perfectly. However, the error message 'Incorrect dataset used for model training' is partially correct compared to the Ground Truth Error 1 message 'ValueError: Found input variables with inconsistent numbers of samples: [268, 623]' indicating the problem with the dataset used in model training, hence a score of 0.5. The error type itself should be 'ValueError', which LLM's output did not specify, resulting in a score of 0 for error type."}, {"cause_line_score": 1, "effect_line_score": 1, "error_type_score": 0, "error_message_score": 0.5, "error_message_eval_reason": "The cause and effect lines in the LLM's output holistically matched Ground Truth Error 2 perfectly. However, the error type (ValueError) was not stated in the LLM output, resulting in a score of 0 for error type. The error message 'Incorrect dataset used for predictions' is partially correct, as it correctly describes the issue but is much less specific than the detailed error message found in Ground Truth Error 2. Therefore, it receives a score of 0.5."}]]}
{"id": 304, "eval_result": [[{"cause_line_score": 1, "effect_line_score": 1, "error_type_score": 0, "error_message_score": 0.5, "error_message_eval_reason": "Cause and effect lines matched Ground Truth Error 1 perfectly. However, the error type ('Incorrect model training data used') is different from the error type in Ground Truth Error 1 ('ValueError: Found input variables with inconsistent numbers of samples: [268, 623]'). The error message was partially correct, as it vaguely describes the issue but lacks specificity and detail - hence the 0.5 score."}, {"cause_line_score": 1, "effect_line_score": 0, "error_type_score": 0, "error_message_score": 0.25, "error_message_eval_reason": "LLM matches Ground Truth Error 2 cause line - Effect line differs. Error message descends data interplay without key details - only loosely related. Overall context considered."}, {"cause_line_score": 1, "effect_line_score": 1, "error_type_score": 0, "error_message_score": 0.25, "error_message_eval_reason": "Cause and Effect lines matched perfectly with Ground Truth Error 3. The error type didn't match as the LLM error message was vague and did not specify the ValueError due to inconsistent sample sizes, leading to an error message score of 0.25."}]]}
{"id": 305, "eval_result": [[{"cause_line_score": 1, "effect_line_score": 0, "error_type_score": 0, "error_message_score": 0.0, "error_message_eval_reason": "No holistic match found with any error instance in Ground Truth Errors list."}, {"cause_line_score": 1, "effect_line_score": 1, "error_type_score": 1, "error_message_score": 1.0, "error_message_eval_reason": "Holistically matched Ground Truth Error 5 perfectly. The cause line and effect line in the LLM Output exactly match those in Ground Truth Error 5. The error type (KeyError) and the error message ('KeyError: \"['Cabin'] not found in axis\"') also match exactly."}, {"cause_line_score": 0, "effect_line_score": 0, "error_type_score": 0, "error_message_score": 0.0, "error_message_eval_reason": "No holistic match found with any error instance in Ground Truth Errors list. The LLM's detected error has a unique cause line, effect line, and error message that do not align with any specific error instance in the Ground Truth."}, {"cause_line_score": 0, "effect_line_score": 1, "error_type_score": 0, "error_message_score": 0.25, "error_message_eval_reason": "The LLM's error message indicates an incorrect assignment issue, which is related to Ground Truth Error 4, but lacks the specific details provided in the Ground Truth error message."}]]}
{"id": 306, "eval_result": [[{"cause_line_score": 1, "effect_line_score": 0, "error_type_score": 0, "error_message_score": 0.0, "error_message_eval_reason": "No holistic match found with any error instance in Ground Truth Errors list."}, {"cause_line_score": 1, "effect_line_score": 1, "error_type_score": 1, "error_message_score": 1.0, "error_message_eval_reason": "Holistically matched Ground Truth Error 5 perfectly. All elements - cause line, effect line, error type, and error message - match exactly."}, {"cause_line_score": 0, "effect_line_score": 0, "error_type_score": 0, "error_message_score": 0.0, "error_message_eval_reason": "No holistic match found with any error instance in Ground Truth Errors list."}, {"cause_line_score": 1, "effect_line_score": 1, "error_type_score": 0, "error_message_score": 0.25, "error_message_eval_reason": "Cause and Effect lines matched Ground Truth Error 4, but error type and details in the error message were irrelevant - hence 0.25 score."}]]}
{"id": 307, "eval_result": [[{"cause_line_score": 0, "effect_line_score": 0, "error_type_score": 0, "error_message_score": 0.0, "error_message_eval_reason": "No holistic match found with any error instance in Ground Truth Errors list."}, {"cause_line_score": 1, "effect_line_score": 1, "error_type_score": 1, "error_message_score": 0.75, "error_message_eval_reason": "Holistically matched Ground Truth Error 1. The cause line, effect line, and error type match perfectly. The error message is mostly correct but lacks minor details - the LLM's output omits the specific invalid value '22.0' mentioned in the Ground Truth error message."}, {"cause_line_score": 1, "effect_line_score": 0, "error_type_score": 0, "error_message_score": 0.0, "error_message_eval_reason": "No holistic match found with any error instance in Ground Truth Errors list. The 'Incorrect behavior: Imputed ages not accurate' is a completely different error message compared to the Ground Truth errors."}, {"cause_line_score": 0, "effect_line_score": 0, "error_type_score": 0, "error_message_score": 0.0, "error_message_eval_reason": "No holistic match found with any error instance in Ground Truth Errors list."}]]}
{"id": 308, "eval_result": [[{"cause_line_score": 1, "effect_line_score": 0, "error_type_score": 0, "error_message_score": 0.0, "error_message_eval_reason": "No holistic match found with any error instance in Ground Truth Errors list as cause and effect lines did not match a single specific error instance."}, {"cause_line_score": 1, "effect_line_score": 1, "error_type_score": 1, "error_message_score": 1.0, "error_message_eval_reason": "Holistically matched Ground Truth Error 3 perfectly. The LLM's detected error has the same cause line, effect line, error message, and error type as the third error instance in the Ground Truth Errors list, which is the KeyError due to dropping the 'Cabin' column incorrectly."}, {"cause_line_score": 0, "effect_line_score": 0, "error_type_score": 0, "error_message_score": 0.0, "error_message_eval_reason": "No holistic match found with any error instance in Ground Truth Errors list."}]]}
{"id": 309, "eval_result": []}
{"id": 310, "eval_result": [[{"cause_line_score": 1, "effect_line_score": 0, "error_type_score": 0, "error_message_score": 0.0, "error_message_eval_reason": "No holistic match found with any error instance in Ground Truth Errors list."}, {"cause_line_score": 0, "effect_line_score": 0, "error_type_score": 0, "error_message_score": 0.0, "error_message_eval_reason": "No holistic match found with any error instance in Ground Truth Errors list."}, {"cause_line_score": 1, "effect_line_score": 1, "error_type_score": 1, "error_message_score": 1.0, "error_message_eval_reason": "Holistically matched Ground Truth Error 6 perfectly."}, {"cause_line_score": 0, "effect_line_score": 0, "error_type_score": 0, "error_message_score": 0.0, "error_message_eval_reason": "No holistic match found with any error instance in Ground Truth Errors list: LLM's cause line, effect line, and error message do not correspond to any specific error instance described in the Ground Truth Errors."}]]}
