{"id": 1, "eval_result": [{"cause_line_score": 0, "effect_line_score": 0, "error_type_score": 0, "error_message_score": 0.0, "error_message_eval_reason": "The error message in the LLM Output is completely irrelevant to the Ground Truth. The Ground Truth indicates a ValueError related to the shape of the array passed to the boxplot function in matplotlib, whereas the LLM Output refers to a RuntimeError related to changing the matplotlib backend. These are unrelated errors, and therefore, the description is completely incorrect."}, {"cause_line_score": 0, "effect_line_score": 0, "error_type_score": 0, "error_message_score": 0.0, "error_message_eval_reason": "The LLM Output's error message 'Unknown backend: agg' is completely irrelevant to the Ground Truth error message 'ValueError: not enough values to unpack (expected 2, got 1)'. The two errors are unrelated, indicating that the LLM did not correctly identify the cause or effect lines, nor the error type."}, {"cause_line_score": 0, "effect_line_score": 0, "error_type_score": 0, "error_message_score": 0.0, "error_message_eval_reason": "The error message 'ValueError: Unknown backend 'agg'' is completely irrelevant to the actual error 'TypeError: can't multiply sequence by non-int of type 'numpy.float64'' given in the Ground Truth."}, {"cause_line_score": 1, "effect_line_score": 1, "error_type_score": 1, "error_message_score": 0.75, "error_message_eval_reason": "The error message captures the main content about the unexpected keyword argument 'outliersize', but is missing minor details like 'TypeError: Axes.'."}, {"cause_line_score": 0, "effect_line_score": 0, "error_type_score": 0, "error_message_score": 0.0, "error_message_eval_reason": "The error message in the LLM Output ('RuntimeError: Matplotlib backend 'Agg' is already in use and cannot be changed') is completely irrelevant and incorrect. The Ground Truth error message is 'ValueError: whis must be a float or list of percentiles', which is a different error type and related to the parameters used in the axs[1, 2].boxplot call."}, {"cause_line_score": 0, "effect_line_score": 0, "error_type_score": 0, "error_message_score": 0.0, "error_message_eval_reason": "The error message in the LLM Output (RuntimeError: Matplotlib backend 'Agg' cannot be set after pyplot has been imported) is completely irrelevant to the Ground Truth's error message (ValueError: whis must be a float or list of percentiles), indicating completely different causes and effects."}, {"cause_line_score": 0, "effect_line_score": 0, "error_type_score": 0, "error_message_score": 0.0, "error_message_eval_reason": "The error message 'RuntimeError: matplotlib.use() cannot be called after importing pyplot' is completely irrelevant compared to the Ground Truth error 'ValueError: whis must be a float or list of percentiles'. The LLM's output does not match the cause line, effect line, or error type described in the Ground Truth."}, {"cause_line_score": 0, "effect_line_score": 0, "error_type_score": 0, "error_message_score": 0.0, "error_message_eval_reason": "The LLM output does not match the ground truth in any aspect. The LLM's cause line and effect line references 'matplotlib.use('Agg')' which is unrelated to the actual error in the ground truth, which is caused by an invalid 'whis' parameter in the 'boxplot' method. Furthermore, the error message 'RuntimeError: Cannot switch backends after pyplot has been imported' is entirely different from the ground truth error message 'ValueError: whis must be a float or list of percentiles'. Therefore, the LLM output is completely irrelevant to the ground truth."}]}
{"id": 2, "eval_result": [{"cause_line_score": 0, "effect_line_score": 0, "error_type_score": 0, "error_message_score": 0.0, "error_message_eval_reason": "The LLM output's error message 'purple' is not a valid color or format string is completely irrelevant to the ground truth error message 'ValueError: x and y must have same first dimension, but have shapes (50,) and (400,)."}, {"cause_line_score": 0, "effect_line_score": 1, "error_type_score": 1, "error_message_score": 0.75, "error_message_eval_reason": "The error message in the LLM Output is mostly correct as it matches the main error 'NameError: name 'pd' is not defined'. However, it lacks the detailed suggestion present in the Ground Truth ('Did you mean: 'id'?')."}, {"cause_line_score": 0, "effect_line_score": 0, "error_type_score": 1, "error_message_score": 1.0, "error_message_eval_reason": "The LLM output for the error message 'NameError: name 'matplotplot' is not defined' matches exactly with the Ground Truth."}, {"cause_line_score": 0, "effect_line_score": 0, "error_type_score": 1, "error_message_score": 1.0, "error_message_eval_reason": "The error description in the LLM Output exactly matches the GT ('KeyError: '-z**3 against w + 2'')."}]}
{"id": 3, "eval_result": [{"cause_line_score": 1, "effect_line_score": 1, "error_type_score": 1, "error_message_score": 0.75, "error_message_eval_reason": "The error message in the LLM Output is mostly correct but lacks the minor detail 'Did you mean: 'd'?' present in the Ground Truth."}, {"cause_line_score": 1, "effect_line_score": 1, "error_type_score": 1, "error_message_score": 1.0, "error_message_eval_reason": "The error message provided by the LLM output is identical to the one in the ground truth, including all key details."}, {"cause_line_score": 1, "effect_line_score": 1, "error_type_score": 1, "error_message_score": 0.75, "error_message_eval_reason": "The error message provided by the LLM ('NameError: name 'pd' is not defined') is mostly correct; however, it lacks the minor detail in the GT error message: 'Did you mean: 'd'?'. This suggests the LLM output is missing potential autocorrection hints."}, {"cause_line_score": 0, "effect_line_score": 0, "error_type_score": 0, "error_message_score": 0.75, "error_message_eval_reason": "The error message in the LLM Output correctly identifies the `AttributeError` and specifies the object 'AxesSubplot' and the non-existent method `set_alpha`, which is similar to what the Ground Truth presents. However, the LLM mentions a different method ('set_alpha' instead of 'set_edgecolor') and does not suggest an alternative method ('set_facecolor'), making the error description mostly correct but lacking minor details."}, {"cause_line_score": 0, "effect_line_score": 0, "error_type_score": 0, "error_message_score": 0.0, "error_message_eval_reason": "The error message provided by the LLM Output, 'IndexError: list index out of range', is completely different from the Ground Truth error message, 'TypeError: 'other' must be an instance of matplotlib.axes._base._AxesBase, not a bool'. The two error messages do not share any relevant details or context."}, {"cause_line_score": 1, "effect_line_score": 1, "error_type_score": 1, "error_message_score": 0.75, "error_message_eval_reason": "The error description is mostly correct but lacks the complete context provided in the Ground Truth, specifically the 'TypeError: Axes' part."}]}
{"id": 4, "eval_result": [{"cause_line_score": 1, "effect_line_score": 0, "error_type_score": 1, "error_message_score": 1.0, "error_message_eval_reason": "The error message in the LLM Output exactly matches the error description in the Ground Truth, including all key details."}, {"cause_line_score": 0, "effect_line_score": 0, "error_type_score": 1, "error_message_score": 0.75, "error_message_eval_reason": "The error description in the LLM Output ('TypeError: cannot unpack non-iterable AxesSubplot object') is mostly correct and identifies the main issue. However, it contains a minor detail difference ('AxesSubplot' instead of 'Axes') from the Ground Truth."}, {"cause_line_score": 1, "effect_line_score": 1, "error_type_score": 1, "error_message_score": 0.75, "error_message_eval_reason": "The LLM's error message is mostly correct but lacks the specific suggestion provided in the Ground Truth, i.e., 'Did you mean: 'id'?'. The primary error description 'NameError: name 'pd' is not defined' is present which constitutes the core part of the error."}, {"cause_line_score": 0, "effect_line_score": 0, "error_type_score": 0, "error_message_score": 0.0, "error_message_eval_reason": "The error message provided by the LLM Output does not match the ground truth error message. The ground truth error is related to RGBA sequence length, while the LLM Output error is about an unexpected keyword argument, which is completely irrelevant to the actual error."}, {"cause_line_score": 0, "effect_line_score": 0, "error_type_score": 1, "error_message_score": 1.0, "error_message_eval_reason": "The error message in the LLM output exactly matches the error message in the Ground Truth, as both state that a 'list' object has no attribute 'shape'."}, {"cause_line_score": 0, "effect_line_score": 0, "error_type_score": 0, "error_message_score": 0.0, "error_message_eval_reason": "The LLM Output describes a completely different error message (RuntimeError: Cannot switch backend after initialization) compared to the Ground Truth (TypeError: only length-1 arrays can be converted to Python scalars). Therefore, the error message is completely irrelevant and incorrect."}]}
{"id": 5, "eval_result": [{"cause_line_score": 0, "effect_line_score": 0, "error_type_score": 0, "error_message_score": 0.5, "error_message_eval_reason": "The LLM provided an error message that touches on the shape mismatch issue (x and width must be the same length), but it did not identify the exact ValueError message about shape mismatch details, which indicates a discrepancy in shapes of input arguments."}, {"cause_line_score": 0, "effect_line_score": 1, "error_type_score": 1, "error_message_score": 0.75, "error_message_eval_reason": "The LLM's error message is mostly correct but lacks some details: the ground truth contains information about the exact shapes causing the mismatch (6 and 3), while the LLM's output only mentions the shape (3) without specifying that the mismatch is between this shape and (6)."}, {"cause_line_score": 1, "effect_line_score": 1, "error_type_score": 0, "error_message_score": 0.75, "error_message_eval_reason": "The error message provided by the LLM Output is mostly correct since it identifies the mismatch in dimensions causing the error. However, the error message in the Ground Truth specifies the shapes (3,) and (2,) while the LLM specifies (3,) and (2,), providing a similar level of detail and indicating the same underlying issue, even though the phrasing is slightly different."}]}
{"id": 51, "eval_result": [{"cause_line_score": 1, "effect_line_score": 0, "error_type_score": 1, "error_message_score": 0.75, "error_message_eval_reason": "The error message in the LLM Output is mostly correct but lacks the suggested correction 'Did you mean: id?' which is present in the Ground Truth and gives additional context."}, {"cause_line_score": 1, "effect_line_score": 1, "error_type_score": 1, "error_message_score": 0.75, "error_message_eval_reason": "The error message provided by the LLM is 'NameError: name 'pd' is not defined', which captures the essence of the ground truth error message. However, it misses the additional suggestion provided in the ground truth: 'Did you mean: 'id'?'. This makes the error description mostly correct but lacking minor details."}, {"cause_line_score": 1, "effect_line_score": 0, "error_type_score": 1, "error_message_score": 0.75, "error_message_eval_reason": "The error description in the LLM Output is mostly correct. It identifies the error as a NameError and specifies that 'pd' is not defined. However, it does not include the full suggestion ('Did you mean: id?'), which is a minor detail."}]}
{"id": 52, "eval_result": [{"cause_line_score": 0, "effect_line_score": 0, "error_type_score": 0, "error_message_score": 0.0, "error_message_eval_reason": "The LLM output's error message 'Cannot switch the backend after it has been set.' is completely irrelevant to the provided ground truth, which indicates a ValueError caused by combining two numpy arrays in a vstack operation."}, {"cause_line_score": 0, "effect_line_score": 0, "error_type_score": 0, "error_message_score": 0.0, "error_message_eval_reason": "The error described in the LLM Output (related to calling matplotlib.use) is completely irrelevant to the ValueError described in the Ground Truth, which is related to a shape mismatch when reshaping a numpy array."}, {"cause_line_score": 0, "effect_line_score": 0, "error_type_score": 0, "error_message_score": 0.0, "error_message_eval_reason": "The LLM output error message 'Cannot switch backend after pyplot has been initialized' is completely irrelevant to the ground truth error message 'TypeError: `bins` must be an integer, a string, or an array'. The LLM output is indicating a backend switching issue in matplotlib, whereas the Ground Truth is focused on an issue with the `bins` parameter in a different context."}, {"cause_line_score": 1, "effect_line_score": 0, "error_type_score": 1, "error_message_score": 1.0, "error_message_eval_reason": "The error message in the LLM Output, 'numpy.ndarray' object has no attribute 'values', exactly matches the error message in the Ground Truth."}, {"cause_line_score": 1, "effect_line_score": 1, "error_type_score": 1, "error_message_score": 1.0, "error_message_eval_reason": "The error description matches exactly: both identify an AttributeError with the message that 'numpy.ndarray' object has no attribute 'get_xaxis'."}, {"cause_line_score": 0, "effect_line_score": 0, "error_type_score": 0, "error_message_score": 0.0, "error_message_eval_reason": "The LLM's error message is about 'RuntimeError: matplotlib.use() must be called before importing matplotlib.pyplot' whereas the Ground Truth is 'ValueError: X must have 2 or fewer dimensions'. These error messages are completely different and unrelated to each other."}, {"cause_line_score": 0, "effect_line_score": 0, "error_type_score": 0, "error_message_score": 0.0, "error_message_eval_reason": "The error description in the LLM output is completely irrelevant to the Ground Truth. The LLM output indicates a RuntimeError related to the 'Agg' backend not supporting interactive plots, while the Ground Truth points to an AttributeError for 'set_facecolor' on a 'Line2D' object. These two errors are unrelated in both context and details."}, {"cause_line_score": 1, "effect_line_score": 1, "error_type_score": 0, "error_message_score": 0.5, "error_message_eval_reason": "The error description provided by the LLM ('x and y must be the same size as c') is partially correct but incomplete. The ground truth specifies that the 'c' argument has 200 elements, which is inconsistent with 'x' and 'y' with size 2, indicating a mismatch in the number of elements which is the exact cause of the error."}]}
{"id": 53, "eval_result": [{"cause_line_score": 1, "effect_line_score": 1, "error_type_score": 1, "error_message_score": 0.75, "error_message_eval_reason": "The error description provided by the LLM is mostly correct. Both specify that an attribute is missing. However, the LLM specifies the object as 'Wedge' whereas the Ground Truth specifies the object as 'list'. Despite this difference, the primary issue that an object lacks the 'centers' attribute is clearly conveyed."}, {"cause_line_score": 1, "effect_line_score": 1, "error_type_score": 1, "error_message_score": 0.75, "error_message_eval_reason": "The error description in the LLM output is mostly correct but lacks the full details provided in the Ground Truth; specifically, it doesn't mention the shape mismatch but conveys the main issue."}, {"cause_line_score": 0, "effect_line_score": 0, "error_type_score": 1, "error_message_score": 1.0, "error_message_eval_reason": "The error message 'ValueError: All arrays must be of the same length' exactly matches the error message in the Ground Truth."}]}
{"id": 54, "eval_result": [{"cause_line_score": 1, "effect_line_score": 1, "error_type_score": 1, "error_message_score": 0.75, "error_message_eval_reason": "The error message in the LLM output correctly identifies the 'NameError' and that 'color_to_rgb' is not defined. However, it misses the additional detail regarding the 'free variable referenced before assignment in enclosing scope' which was mentioned in the Ground Truth."}, {"cause_line_score": 0, "effect_line_score": 0, "error_type_score": 0, "error_message_score": 0.0, "error_message_eval_reason": "The error message provided by the LLM ('hsv() takes 1 positional argument but 3 were given') is completely different from the GT error message ('ValueError: RGBA values should be within 0-1 range'). There is no overlap between the details of the error descriptions provided by the LLM and the GT."}, {"cause_line_score": 1, "effect_line_score": 1, "error_type_score": 0, "error_message_score": 0.5, "error_message_eval_reason": "The error message in the LLM output identifies a 'ValueError' and suggests that the input shape is incorrect, which loosely relates to the cause of the error. However, it does not fully capture the details given in the Ground Truth about the inhomogeneous shape after 2 dimensions and the specific array element setting issue. Therefore, it is only partially correct and contains incomplete information."}]}
{"id": 55, "eval_result": [{"cause_line_score": 0, "effect_line_score": 0, "error_type_score": 0, "error_message_score": 0.0, "error_message_eval_reason": "The error description in the LLM Output is completely unrelated to the Ground Truth. The Ground Truth describes a FileNotFoundError caused by the absence of 'data.csv', while the LLM Output describes a RuntimeError related to setting the matplotlib backend after pyplot import, which is a different issue altogether."}]}
{"id": 100, "eval_result": [{"cause_line_score": 1, "effect_line_score": 1, "error_type_score": 1, "error_message_score": 0.75, "error_message_eval_reason": "The error description provided in the LLM Output is mostly correct as it captures the essential issue related to the mismatch in lengths of the replacement lists. However, the wording is not exactly the same as the Ground Truth. The GT specifies 'expecting 11 got 1' while the LLM Output provides a different phrasing 'to_replace has 11 elements, replace has 1 elements', but they both convey the same core message."}]}
{"id": 101, "eval_result": [{"cause_line_score": 1, "effect_line_score": 1, "error_type_score": 0, "error_message_score": 0.5, "error_message_eval_reason": "The error description provided by the LLM ('ValueError: y contains NaN values') is partially correct in that it recognizes the issue of NaN values leading to an error. However, it inaccurately identifies the exact error class 'ValueError' instead of the more specific 'IntCastingNaNError'. Moreover, the lack of detail regarding the inability to cast NaN values to integers further reduces the score."}, {"cause_line_score": 1, "effect_line_score": 1, "error_type_score": 1, "error_message_score": 0.75, "error_message_eval_reason": "The LLM's error description 'Expected 2D array, got 1D array instead' matches the error type and closely relates to the Ground Truth's suggestion to reshape the data. However, it lacks the specific instruction on how to reshape the data (\u2018array.reshape(-1, 1)\u2019 or \u2018array.reshape(1, -1)\u2019), which is a minor detail."}, {"cause_line_score": 1, "effect_line_score": 1, "error_type_score": 1, "error_message_score": 1.0, "error_message_eval_reason": "The error message 'invalid literal for int() with base 10: '22.0'' in the LLM Output exactly matches the error message in the Ground Truth. There are no discrepancies or missing details."}, {"cause_line_score": 1, "effect_line_score": 1, "error_type_score": 1, "error_message_score": 0.75, "error_message_eval_reason": "The error message in the LLM Output is mostly correct as it includes the key part of the error: 'ValueError: Unknown label type: 'continuous''. However, it lacks the additional explanatory details provided in the Ground Truth: 'Maybe you are trying to fit a classifier, which expects discrete classes on a regression target with continuous values.'"}, {"cause_line_score": 1, "effect_line_score": 1, "error_type_score": 0, "error_message_score": 0.5, "error_message_eval_reason": "The error message in the LLM output captures the essence of the error but is not an exact match. The ground truth specifies 'ValueError: Must have equal len keys and value when setting with an iterable', while the LLM output states 'ValueError: Length of values does not match index'. Both messages describe a value length mismatch issue, but the exact phrasing differs, indicating partial correctness and incomplete detail in the LLM's message."}, {"cause_line_score": 1, "effect_line_score": 0, "error_type_score": 0, "error_message_score": 0.75, "error_message_eval_reason": "The error description in the LLM Output is mostly correct but lacks minor details. Specifically, it identifies a length mismatch error, which is the correct type of error, but does not match the exact wording in the GT error message."}, {"cause_line_score": 1, "effect_line_score": 1, "error_type_score": 1, "error_message_score": 1.0, "error_message_eval_reason": "The error message 'KeyError: \"['Cabin'] not found in axis\"' in the LLM Output exactly matches the error message in the Ground Truth including all key details, hence it scores 1.0."}, {"cause_line_score": 0, "effect_line_score": 0, "error_type_score": 0, "error_message_score": 0.0, "error_message_eval_reason": "The LLM output's error message is completely different from the ground truth. The ground truth indicates a 'ValueError' related to shape mismatch, whereas the LLM output indicates an issue with showing the plot using a non-interactive backend. Therefore, the error description is completely irrelevant or incorrect."}, {"cause_line_score": 1, "effect_line_score": 1, "error_type_score": 0, "error_message_score": 0.0, "error_message_eval_reason": "The error message in the LLM Output indicates a 'TypeError' due to a 'list' object being interpreted as a float, which is not relevant or related to the Ground Truth's 'ValueError' regarding a shape mismatch. Therefore, the error type doesn't match, and the error message is completely irrelevant."}, {"cause_line_score": 0, "effect_line_score": 0, "error_type_score": 0, "error_message_score": 0.0, "error_message_eval_reason": "The LLM output error is entirely different from the ground truth. The error message 'Length of values (1782) does not match length of index (891)' in the ground truth indicates a ValueError related to mismatched lengths, while the LLM output error message is related to a 'list' object not having 'keys'. Therefore, all scores are zero."}]}
{"id": 102, "eval_result": [{"cause_line_score": 1, "effect_line_score": 1, "error_type_score": 1, "error_message_score": 1.0, "error_message_eval_reason": "The error description in the LLM Output exactly matches the GT (KeyError: 'Parch')."}]}
{"id": 103, "eval_result": [{"cause_line_score": 1, "effect_line_score": 0, "error_type_score": 1, "error_message_score": 1.0, "error_message_eval_reason": "The LLM Output's error message 'KeyError: 'sex'' exactly matches the error message in the Ground Truth, including all key details."}, {"cause_line_score": 1, "effect_line_score": 0, "error_type_score": 1, "error_message_score": 1.0, "error_message_eval_reason": "The error message KeyError: 'sex' in the LLM Output exactly matches the error message in the Ground Truth."}, {"cause_line_score": 1, "effect_line_score": 0, "error_type_score": 1, "error_message_score": 1.0, "error_message_eval_reason": "The error message 'KeyError: 'sex'' provided by the LLM Output exactly matches the Ground Truth, including all key details."}, {"cause_line_score": 0, "effect_line_score": 0, "error_type_score": 0, "error_message_score": 0.0, "error_message_eval_reason": "The error description in the LLM Output 'RuntimeError: show is not supported by the 'Agg' backend' is completely different from the Ground Truth error 'KeyError: 'sex''. The error types and their causes are entirely unrelated."}]}
{"id": 104, "eval_result": [{"cause_line_score": 1, "effect_line_score": 1, "error_type_score": 1, "error_message_score": 1.0, "error_message_eval_reason": "The error message 'KeyError: 'Rings''' in the LLM Output exactly matches the error message in the Ground Truth, including all key details."}, {"cause_line_score": 1, "effect_line_score": 0, "error_type_score": 0, "error_message_score": 0.0, "error_message_eval_reason": "The error message in the LLM output is completely irrelevant to the provided Ground Truth. The Ground Truth error message concerns handling missing values encoded as NaNs, while the LLM output error message is about a length mismatch in DataFrame columns, which is a different issue altogether."}, {"cause_line_score": 1, "effect_line_score": 1, "error_type_score": 1, "error_message_score": 1.0, "error_message_eval_reason": "The error message in the LLM output exactly matches the Ground Truth, providing all key details. Both describe a 'Length mismatch: Expected axis has 8 elements, new values have 9 elements' which is correct and complete."}, {"cause_line_score": 1, "effect_line_score": 1, "error_type_score": 1, "error_message_score": 0.75, "error_message_eval_reason": "The LLM's error message essentially identifies the length mismatch issue, as mentioned in the GT. However, the LLM's description 'Expected 9 columns but got 8 columns' is less precise compared to the GT's message, 'Expected axis has 8 elements, new values have 9 elements'."}, {"cause_line_score": 1, "effect_line_score": 1, "error_type_score": 1, "error_message_score": 1.0, "error_message_eval_reason": "The error message in the LLM Output exactly matches the error message described in the Ground Truth as '__init__() got an unexpected keyword argument 'normalize''. This includes all the key details of the error."}, {"cause_line_score": 0, "effect_line_score": 1, "error_type_score": 1, "error_message_score": 0.75, "error_message_eval_reason": "The error message in the LLM Output mostly matches the Ground Truth, accurately describing the inconsistency in the sample sizes of X_test and y_train. However, it phrases it slightly differently and lacks specific numerical details."}, {"cause_line_score": 1, "effect_line_score": 1, "error_type_score": 1, "error_message_score": 0.75, "error_message_eval_reason": "The error message in the LLM output 'Found input variables with inconsistent numbers of samples' captures the essential detail of the ground truth message 'ValueError: Found input variables with inconsistent numbers of samples: [1254, 2923]'. However, it lacks the specific details about the number of samples, which makes it mostly correct but incomplete."}, {"cause_line_score": 1, "effect_line_score": 1, "error_type_score": 1, "error_message_score": 0.75, "error_message_eval_reason": "The error description in the LLM Output 'Found input variables with inconsistent numbers of samples' is mostly correct but lacks the exact details of the samples size '[2923, 1254]' listed in the Ground Truth."}, {"cause_line_score": 1, "effect_line_score": 1, "error_type_score": 1, "error_message_score": 1.0, "error_message_eval_reason": "The error description in the LLM Output exactly matches the Ground Truth, including all key details."}, {"cause_line_score": 1, "effect_line_score": 0, "error_type_score": 1, "error_message_score": 0.75, "error_message_eval_reason": "The error description in the LLM Output is mostly correct and matches the GT error message, but it lacks the specific details about the sample sizes (1254 and 2923)."}, {"cause_line_score": 1, "effect_line_score": 1, "error_type_score": 1, "error_message_score": 0.75, "error_message_eval_reason": "The LLM output error message is mostly correct but lacks the specific detail about the exact number of samples that caused the inconsistency (1254 and 2923). The essence of the error is correctly captured."}, {"cause_line_score": 1, "effect_line_score": 1, "error_type_score": 0, "error_message_score": 0.5, "error_message_eval_reason": "The LLM's error description mentions an incorrect usage of y_train instead of y_test, which is not relevant in this case. The actual error pertains to inconsistent numbers of samples between y_train and y_pred_volume. The LLM Output correctly identifies there is an issue with the line provided but misinterprets the nature of the error."}, {"cause_line_score": 0, "effect_line_score": 0, "error_type_score": 1, "error_message_score": 1.0, "error_message_eval_reason": "The error message 'KeyError: 'weight'' exactly matches the error type described in the Ground Truth 'KeyError: 'length'' albeit with a different key. Since the task is to match the error type, the score is given as 1.0."}, {"cause_line_score": 0, "effect_line_score": 0, "error_type_score": 0, "error_message_score": 0.0, "error_message_eval_reason": "The LLM output indicates a KeyError for a missing column 'Weight', which is incorrect. The ground truth indicates a TypeError due to an issue with converting a list of string values to numeric in a fillna operation. The error messages and the lines of code causing and affected by the error are completely different, leading to scores of 0 in all categories."}]}
{"id": 151, "eval_result": [{"cause_line_score": 0, "effect_line_score": 0, "error_type_score": 0, "error_message_score": 0.0, "error_message_eval_reason": "The LLM output's error message is completely irrelevant to the Ground Truth. The Ground Truth error is a FileNotFoundError related to a missing CSV file, whereas the LLM output mentions an error regarding incorrectly identifying the region with the lowest average balance, which is unrelated to the file not found issue."}, {"cause_line_score": 0, "effect_line_score": 0, "error_type_score": 0, "error_message_score": 0.0, "error_message_eval_reason": "The error in the LLM output is a KeyError while the Ground Truth specifies an AttributeError. This means that not only is the error message incorrect, but the cause and effect lines are also different as they relate to different errors."}, {"cause_line_score": 0, "effect_line_score": 0, "error_type_score": 0, "error_message_score": 0.0, "error_message_eval_reason": "The error message in the LLM Output is 'KeyError: 'Region'' which is completely different from the GT error message 'AttributeError: 'NoneType' object has no attribute 'drop''. Therefore, it is incorrect and irrelevant."}]}
{"id": 152, "eval_result": [{"cause_line_score": 0, "effect_line_score": 0, "error_type_score": 0, "error_message_score": 0.0, "error_message_eval_reason": "The error description provided ('KeyError: 'Final Worth (USD)'') is completely irrelevant and incorrect compared to the ground truth error of 'urllib.error.HTTPError: HTTP Error 404: Not Found'."}, {"cause_line_score": 0, "effect_line_score": 0, "error_type_score": 0, "error_message_score": 0.0, "error_message_eval_reason": "The error description provided by the LLM is completely irrelevant to the actual error message, which is related to a missing file, not bin ranges."}, {"cause_line_score": 0, "effect_line_score": 0, "error_type_score": 0, "error_message_score": 0.0, "error_message_eval_reason": "The LLM's error message reports a KeyError for 'Net Worth', which is completely irrelevant to the Ground Truth error message of FileNotFoundError for 'billionaires.csv'."}, {"cause_line_score": 0, "effect_line_score": 0, "error_type_score": 0, "error_message_score": 0.0, "error_message_eval_reason": "The error description provided by the LLM is completely irrelevant to the Ground Truth. The Ground Truth indicates a 'FileNotFoundError', while the LLM output indicates a 'ValueError', which is a completely different type of error with a different cause and effect."}]}
{"id": 153, "eval_result": [{"cause_line_score": 0, "effect_line_score": 0, "error_type_score": 0, "error_message_score": 0.0, "error_message_eval_reason": "The error message from the LLM Output discusses columns that do not exist, whereas the Ground Truth error message indicates a TypeError related to a 'NoneType' object. The two error messages are not related, hence it is completely irrelevant."}, {"cause_line_score": 0, "effect_line_score": 0, "error_type_score": 0, "error_message_score": 0.0, "error_message_eval_reason": "The LLM's output has no overlap with the Ground Truth. The cause_line is different, the effect_line is different, and the error_message describes a different error ('cut() got an unexpected keyword argument 'dtype'') compared to the Ground Truth's FileNotFoundError. Therefore, the error message is completely irrelevant."}, {"cause_line_score": 0, "effect_line_score": 0, "error_type_score": 0, "error_message_score": 0.0, "error_message_eval_reason": "The LLM's output does not match the ground truth in any of the dimensions. The cause line 'return dataset.drop(columns=['Checkup'])' and effect line 'dataset = drop_checkup(dataset)' do not match the ground truth 'main()' for both. The error type 'KeyError' in the LLM output does not match the ground truth 'TypeError'. The error message 'KeyError: 'Checkup'' is completely different from 'TypeError: 'NoneType' object is not subscriptable'. Therefore, all scores are zero."}, {"cause_line_score": 0, "effect_line_score": 0, "error_type_score": 0, "error_message_score": 0.0, "error_message_eval_reason": "The error message provided by the LLM Output 'KeyError: 'Checkup'' is completely irrelevant to the Ground Truth error message 'urllib.error.HTTPError: HTTP Error 404: Not Found'. Therefore, it scores 0.0."}]}
{"id": 154, "eval_result": [{"cause_line_score": 0, "effect_line_score": 0, "error_type_score": 0, "error_message_score": 0.0, "error_message_eval_reason": "The error message provided by the LLM (\"KeyError: '[ICO Number] not found in axis'\") is completely irrelevant to the Ground Truth error message (\"AttributeError: 'NoneType' object has no attribute 'drop_duplicates'\")."}, {"cause_line_score": 0, "effect_line_score": 0, "error_type_score": 0, "error_message_score": 0.0, "error_message_eval_reason": "The LLM Output mentioned a completely different operation and error from the Ground Truth. The Ground Truth indicates an AttributeError due to the 'NoneType' object not having a 'drop_duplicates' attribute, while the LLM Output mentions a KeyError for a column not found during a drop operation. These errors are unrelated, hence the score is completely irrelevant."}, {"cause_line_score": 0, "effect_line_score": 0, "error_type_score": 0, "error_message_score": 0.0, "error_message_eval_reason": "The error description in the LLM Output is entirely different from the Ground Truth. The Ground Truth is about an AttributeError while the LLM Output describes a KeyError."}, {"cause_line_score": 0, "effect_line_score": 0, "error_type_score": 0, "error_message_score": 0.0, "error_message_eval_reason": "The error description in the LLM Output (KeyError: 'ICO Number') does not match the Ground Truth error description. The Ground Truth error description indicates an AttributeError related to a NoneType object, while the LLM Output mentions a KeyError related to a missing column 'ICO Number'. Thus, the error description is completely irrelevant or incorrect."}]}
{"id": 155, "eval_result": [{"cause_line_score": 0, "effect_line_score": 0, "error_type_score": 0, "error_message_score": 0.0, "error_message_eval_reason": "The LLM's error message 'KeyError: 'Currency Conversion Rate'' does not match the GT error message 'FileNotFoundError: [Errno 2] No such file or directory: 'salaries.csv'. The error description is completely different and indicates a different problem in the code."}]}
