{"id": 1, "eval_result": [{"cause_line_score": 1, "effect_line_score": 1, "error_type_score": 0, "error_message_score": 0.0, "error_message_eval_reason": "The error message described a TypeError related to ufunc 'isfinite', which is completely irrelevant to the ValueError concerning the dimensionality of X."}, {"cause_line_score": 1, "effect_line_score": 1, "error_type_score": 0, "error_message_score": 0.0, "error_message_eval_reason": "The error message in the LLM Output is completely different from the Ground Truth. The Ground Truth indicates a 'ValueError' with a specific message about unpacking values, whereas the LLM Output mentions a 'TypeError' related to interpreting a list as an integer. Thus, the LLM's error message is completely incorrect and irrelevant to the Ground Truth."}, {"cause_line_score": 0, "effect_line_score": 0, "error_type_score": 0, "error_message_score": 0.0, "error_message_eval_reason": "The error message in the LLM Output is completely irrelevant. The Ground Truth error message is a 'TypeError: can't multiply sequence by non-int of type 'numpy.float64'', whereas the LLM Output error message is 'TypeError: boxplot() got an unexpected keyword argument 'color''. The errors are different in nature and context."}, {"cause_line_score": 1, "effect_line_score": 1, "error_type_score": 1, "error_message_score": 0.75, "error_message_eval_reason": "The error message in the LLM Output captures the main issue (unexpected keyword argument 'outliersize'), but it omits the function or method name (`Axes.boxplot()`) mentioned in the Ground Truth."}, {"cause_line_score": 0, "effect_line_score": 0, "error_type_score": 0, "error_message_score": 0.0, "error_message_eval_reason": "The LLM's output does not match the GT cause or effect lines. Furthermore, the LLM's error message 'The boxplot is already horizontal, so the title 'Horizontal Boxplot' is redundant and misleading.' is completely irrelevant to the GT error message 'ValueError: whis must be a float or list of percentiles'. Therefore, the error description provided by the LLM is entirely incorrect and does not align with the GT."}, {"cause_line_score": 1, "effect_line_score": 1, "error_type_score": 0, "error_message_score": 0.0, "error_message_eval_reason": "The error message provided by the LLM is 'TypeError: 'str' object cannot be interpreted as an integer', which is completely irrelevant to the actual error 'ValueError: whis must be a float or list of percentiles'. These two errors are entirely different in nature and context."}, {"cause_line_score": 0, "effect_line_score": 0, "error_type_score": 0, "error_message_score": 0.0, "error_message_eval_reason": "The LLM's provided cause line, effect line, and error message are completely different from the Ground Truth. The GT error is about the 'whis' parameter needing to be a float or list of percentiles in a boxplot function, while the LLM's output suggests an error about the 'set_prop_cycle' method not being present in an 'AxesSubplot' object."}, {"cause_line_score": 0, "effect_line_score": 0, "error_type_score": 0, "error_message_score": 0.0, "error_message_eval_reason": "The LLM Output is completely incorrect. The `cause_line` and `effect_line` do not match the Ground Truth at all. The error type is also different as the Ground Truth specified the error is due to 'whis' requiring a float or list of percentiles, while the LLM focused on 'patch_artist' being set to True, which is unrelated to the actual error. Therefore, the error message in the LLM Output is entirely irrelevant as it addresses a different issue."}]}
{"id": 2, "eval_result": [{"cause_line_score": 0, "effect_line_score": 0, "error_type_score": 0, "error_message_score": 0.0, "error_message_eval_reason": "The error description provided by the LLM is completely irrelevant to the actual error described in the Ground Truth. The Ground Truth describes a size mismatch issue between two arrays (x and y) with a specific ValueError, whereas the LLM describes an issue related to disabling y-axis labels which does not relate to the Ground Truth error at all."}, {"cause_line_score": 0, "effect_line_score": 0, "error_type_score": 0, "error_message_score": 0.0, "error_message_eval_reason": "The error description provided by the LLM Output ('TypeError: ufunc 'add' did not contain a loop with signature matching types (dtype('float64'), dtype('O')) -> dtype('O')') is completely different from the Ground Truth's error message ('NameError: name 'pd' is not defined. Did you mean: 'id'?'). Therefore, it is irrelevant to the actual error."}, {"cause_line_score": 1, "effect_line_score": 0, "error_type_score": 1, "error_message_score": 1.0, "error_message_eval_reason": "The error message in the LLM Output matches the Ground Truth exactly, including all key details about the NameError and the suggestion of 'matplotlib'."}, {"cause_line_score": 0, "effect_line_score": 1, "error_type_score": 1, "error_message_score": 1.0, "error_message_eval_reason": "The error message in the LLM output exactly matches the error message in the ground truth, the KeyError for '-z**3 against w + 2'."}, {"cause_line_score": 0, "effect_line_score": 0, "error_type_score": 1, "error_message_score": 0.25, "error_message_eval_reason": "The error description provided by the LLM Output ('KeyError: 'z^3 against w'') is only loosely related to the Ground Truth error ('KeyError: '1''). While both involve a KeyError, they refer to different keys and contexts, thus making the provided error message mostly irrelevant to the Ground Truth description."}]}
{"id": 3, "eval_result": [{"cause_line_score": 1, "effect_line_score": 1, "error_type_score": 0, "error_message_score": 0.0, "error_message_eval_reason": "The LLM's error message (TypeError: must be str, not DataFrame) does not match the Ground Truth error message (NameError: name 'pd' is not defined). The error descriptions are completely different and refer to different types of error."}, {"cause_line_score": 1, "effect_line_score": 0, "error_type_score": 0, "error_message_score": 0.25, "error_message_eval_reason": "The LLM identified the line causing the error correctly but misunderstood the effect line. The error message in the LLM Output mentions an order issue with the quartiles, which is not the actual problem. The GT error is about a reduction operation on a zero-size array, which is loosely related but factually incorrect in the LLM response."}, {"cause_line_score": 1, "effect_line_score": 1, "error_type_score": 1, "error_message_score": 0.75, "error_message_eval_reason": "The error message in the LLM output is mostly correct, however, it lacks the suggested correction ('Did you mean: 'd'?') provided in the ground truth."}, {"cause_line_score": 0, "effect_line_score": 0, "error_type_score": 0, "error_message_score": 0.0, "error_message_eval_reason": "The error message provided by the LLM is completely irrelevant to the ground truth. The LLM mentions a TypeError regarding 'numpy.ndarray' being not iterable, whereas the actual error is an AttributeError related to the 'set_edgecolor' method not being present on the 'Axes' object."}, {"cause_line_score": 0, "effect_line_score": 0, "error_type_score": 0, "error_message_score": 0.0, "error_message_eval_reason": "The error message in the LLM output ('unexpected keyword argument') is entirely different from the ground truth ('must be an instance of matplotlib.axes._base._AxesBase, not a bool'), making it completely irrelevant."}, {"cause_line_score": 1, "effect_line_score": 1, "error_type_score": 1, "error_message_score": 1.0, "error_message_eval_reason": "The error description 'violinplot() got an unexpected keyword argument 'body'' exactly matches the Ground Truth error message in key details and content."}]}
{"id": 4, "eval_result": [{"cause_line_score": 1, "effect_line_score": 1, "error_type_score": 0, "error_message_score": 0.0, "error_message_eval_reason": "The error description in the LLM output 'ValueError: shapes (2,2) and (500,2) not aligned: 2 (dim 1) != 500 (dim 0)' is completely irrelevant compared to the GT error description 'AttributeError: 'list' object has no attribute 'dot'' which indicates a type error due to calling a method on an inappropriate object type."}, {"cause_line_score": 0, "effect_line_score": 0, "error_type_score": 0, "error_message_score": 0.0, "error_message_eval_reason": "The provided error message in the LLM output is completely irrelevant to the actual error indicated in the Ground Truth. The Ground Truth error is a TypeError related to unpacking a non-iterable Axes object, while the LLM output error message refers to a mismatch in data point numbers."}, {"cause_line_score": 1, "effect_line_score": 1, "error_type_score": 0, "error_message_score": 0.0, "error_message_eval_reason": "The Ground Truth error message indicates a NameError due to 'pd' not being defined. However, the LLM Output states that no error is thrown and suggests unnecessary complexity. This is completely irrelevant to the actual error."}, {"cause_line_score": 0, "effect_line_score": 0, "error_type_score": 0, "error_message_score": 0.0, "error_message_eval_reason": "The LLM Output's error message is not correct. The Ground Truth error clearly indicates that the issue is a ValueError due to an RGBA sequence having an incorrect length, whereas the LLM Output incorrectly suggests an issue with the scaling of the ellipses."}, {"cause_line_score": 0, "effect_line_score": 0, "error_type_score": 0, "error_message_score": 0.0, "error_message_eval_reason": "The LLM Output doesn't match the Ground Truth in terms of error type and message. The Ground Truth indicates an AttributeError related to a list not having the 'shape' attribute, while the LLM Output discusses a redundant ellipse drawing for legend labels, which is completely unrelated to the actual error."}, {"cause_line_score": 0, "effect_line_score": 0, "error_type_score": 0, "error_message_score": 0.0, "error_message_eval_reason": "The LLM Output completely mismatches the Ground Truth in all evaluated dimensions. The cause and effect lines are different, and the error message given by the LLM ('The legend will show a red ellipse, which is not present in the plot, leading to confusion.') is completely irrelevant compared to the Ground Truth error ('TypeError: only length-1 arrays can be converted to Python scalars'). Thus, the scores for cause_line_score, effect_line_score, and error_type_score are 0, and the error_message_score is 0.0."}]}
{"id": 5, "eval_result": [{"cause_line_score": 0, "effect_line_score": 0, "error_type_score": 0, "error_message_score": 0.25, "error_message_eval_reason": "The LLM's error description is loosely related to the GT but misses details about object shapes and broadcasting."}, {"cause_line_score": 1, "effect_line_score": 1, "error_type_score": 1, "error_message_score": 0.75, "error_message_eval_reason": "The error message provided by the LLM Output ('ValueError: operands could not be broadcast together with shapes (6,) (3,)') is very similar to the Ground Truth ('ValueError: shape mismatch: objects cannot be broadcast to a single shape. Mismatch is between arg 0 with shape (6,) and arg 3 with shape (3,).'). The error type and the core issue of shape mismatch are correctly identified, but the specific details of 'arg 0' and 'arg 3' are missing in the LLM Output."}, {"cause_line_score": 1, "effect_line_score": 1, "error_type_score": 1, "error_message_score": 0.5, "error_message_eval_reason": "The LLM Output correctly identifies the shapes involved in the broadcasting issue, but the exact details of the mismatch differ slightly from the Ground Truth. The GT mentions a mismatch between arg 0 with shape (3,) and arg 1 with shape (2,), while the LLM Output mentions shapes (3,) and (2,3). This indicates partial correctness but not an exact match."}]}
{"id": 51, "eval_result": [{"cause_line_score": 1, "effect_line_score": 0, "error_type_score": 1, "error_message_score": 0.75, "error_message_eval_reason": "The error description 'NameError: name 'pd' is not defined' in the LLM output mostly matches the Ground Truth 'NameError: name 'pd' is not defined. Did you mean: 'id'?'. It captures the main issue (NameError due to 'pd' not being defined), but it lacks the suggestion 'Did you mean: 'id'?' from the Ground Truth, which is a minor detail."}, {"cause_line_score": 1, "effect_line_score": 0, "error_type_score": 1, "error_message_score": 0.75, "error_message_eval_reason": "The error message in the LLM Output is mostly correct: 'NameError: name 'pd' is not defined'. However, it omits the additional helpful suggestion found in the Ground Truth, 'Did you mean: 'id'?'."}, {"cause_line_score": 1, "effect_line_score": 1, "error_type_score": 0, "error_message_score": 0.0, "error_message_eval_reason": "The error message provided by the LLM is completely incorrect. The Ground Truth identifies a 'NameError: name 'pd' is not defined', which is a NameError due to a missing import of the pandas (pd) library. The LLM's output incorrectly identifies the error as 'TypeError: must be str, not Series', which is unrelated to the import error."}]}
{"id": 52, "eval_result": [{"cause_line_score": 0, "effect_line_score": 0, "error_type_score": 0, "error_message_score": 0.0, "error_message_eval_reason": "The LLM's output is entirely unrelated to the Ground Truth. The LLM points to a matplotlib configuration issue, whereas the Ground Truth indicates a problem related to data structure compatibility with pandas DataFrame creation."}, {"cause_line_score": 1, "effect_line_score": 0, "error_type_score": 0, "error_message_score": 0.0, "error_message_eval_reason": "The error in the LLM Output ('AttributeError: 'numpy.ndarray' object has no attribute 'values'') is completely different from the error in the Ground Truth ('ValueError: shape mismatch: value array of shape (2,) could not be broadcast to indexing result of shape (2,1)'). The LLM Output is incorrect and does not match the type or description of the Ground Truth error."}, {"cause_line_score": 0, "effect_line_score": 0, "error_type_score": 0, "error_message_score": 0.0, "error_message_eval_reason": "The LLM's output does not match the Ground Truth in any of the dimensions: the cause line and effect line are both incorrect, and the error message describes a completely different issue (overlapping boxplots with beeswarm points) rather than the TypeError related to the `bins` argument needing to be an integer, a string, or an array."}, {"cause_line_score": 1, "effect_line_score": 0, "error_type_score": 1, "error_message_score": 1.0, "error_message_eval_reason": "The error message in the LLM Output exactly matches the Ground Truth, including the key details of the error."}, {"cause_line_score": 1, "effect_line_score": 0, "error_type_score": 0, "error_message_score": 0.0, "error_message_eval_reason": "The error message from the LLM output 'TypeError: 'numpy.ndarray' object is not callable' does not match the Ground Truth 'AttributeError: 'numpy.ndarray' object has no attribute 'get_xaxis'. The two error types and descriptions are completely different."}, {"cause_line_score": 1, "effect_line_score": 0, "error_type_score": 0, "error_message_score": 0.0, "error_message_eval_reason": "The error description in the LLM Output (ValueError: The truth value of an array with more than one element is ambiguous. Use a.any() or a.all()) does not match the ground truth error description (ValueError: X must have 2 or fewer dimensions). The two errors refer to different issues and are not related."}, {"cause_line_score": 0, "effect_line_score": 0, "error_type_score": 0, "error_message_score": 0.0, "error_message_eval_reason": "The error description provided by the LLM Output is completely irrelevant to the Ground Truth. The Ground Truth refers to an AttributeError due to 'set_facecolor' not being a method for a 'Line2D' object, whereas the LLM Output talks about the y-axis limits being too narrow which is not related to the actual error."}, {"cause_line_score": 1, "effect_line_score": 1, "error_type_score": 1, "error_message_score": 1.0, "error_message_eval_reason": "The LLM Output error message exactly matches the Ground Truth error message, including all key details: 'ValueError: 'c' argument has 200 elements, which is inconsistent with 'x' and 'y' with size 2.'"}]}
{"id": 53, "eval_result": [{"cause_line_score": 0, "effect_line_score": 0, "error_type_score": 1, "error_message_score": 1.0, "error_message_eval_reason": "The error message provided in the LLM Output exactly matches the error message in the Ground Truth, including all key details."}, {"cause_line_score": 1, "effect_line_score": 1, "error_type_score": 0, "error_message_score": 0.5, "error_message_eval_reason": "The LLM Output indicates that the lines will not be drawn correctly and that the plot will not show the intended connections between the apple slice and the bar chart. However, it does not correctly identify the specific error message: 'ValueError: x and y must have same first dimension, but have shapes (5,) and (4,)', which indicates a mismatch in the dimensions of the x and y arrays."}, {"cause_line_score": 0, "effect_line_score": 0, "error_type_score": 0, "error_message_score": 0.0, "error_message_eval_reason": "The LLM output's error description about the lines connecting the pie chart slice to the bar chart not being drawn is completely irrelevant to the Ground Truth's error message, which indicates a ValueError regarding array lengths."}]}
{"id": 54, "eval_result": [{"cause_line_score": 1, "effect_line_score": 1, "error_type_score": 1, "error_message_score": 0.75, "error_message_eval_reason": "The error message provided by the LLM ('name 'color_to_rgb' is not defined') is mostly correct as it aligns with the ground truth error message which states that 'color_to_rgb' is not defined. However, it lacks the specific detail about the 'free variable' referenced before assignment in the enclosing scope which provides additional context."}, {"cause_line_score": 0, "effect_line_score": 0, "error_type_score": 0, "error_message_score": 0.25, "error_message_eval_reason": "The error message in the LLM output ('ValueError: hue must be in the range [0, 1]') is only loosely related to the Ground Truth ('ValueError: RGBA values should be within 0-1 range'). Both mention a range issue, but they pertain to different parameters within the code, making the match weak."}, {"cause_line_score": 0, "effect_line_score": 0, "error_type_score": 0, "error_message_score": 0.25, "error_message_eval_reason": "The error message provided by the LLM Output is loosely related to the Ground Truth error message. Both the Ground Truth and LLM indicate a ValueError, however the actual description of the error differs significantly. The Ground Truth mentions an issue with setting an array element with a sequence and having an inhomogeneous shape, while the LLM's error message talks about an invalid rgba argument."}]}
{"id": 55, "eval_result": [{"cause_line_score": 0, "effect_line_score": 0, "error_type_score": 0, "error_message_score": 0.0, "error_message_eval_reason": "The LLM's error description is completely irrelevant to the Ground Truth. The Ground Truth error message indicates a FileNotFoundError due to a missing file, while the LLM's error message talks about incorrect y-axis limits in plotting, which is not related to the issue of a missing file at all."}]}
{"id": 100, "eval_result": [{"cause_line_score": 1, "effect_line_score": 1, "error_type_score": 0, "error_message_score": 0.25, "error_message_eval_reason": "The LLM incorrectly identified the error type as a TypeError instead of a ValueError. Additionally, the error description provided by the LLM ('replace() argument must be str, tuple, list, dict, int, float, or None, not 'list'') is only loosely related to the actual error message ('Replacement lists must match in length. Expecting 11 got 1'). It mentions a list issue but does not convey the key details of the length mismatch."}]}
{"id": 101, "eval_result": [{"cause_line_score": 1, "effect_line_score": 1, "error_type_score": 0, "error_message_score": 0.5, "error_message_eval_reason": "The error message 'ValueError: Input contains NaN' indicates that there are NaN values in the input, which is a related but less specific description compared to the ground truth error 'pandas.errors.IntCastingNaNError: Cannot convert non-finite values (NA or inf) to integer'. The key detail about converting non-finite values to integer is missing, but it is still partially correct and related to the ground truth error."}, {"cause_line_score": 0, "effect_line_score": 1, "error_type_score": 0, "error_message_score": 0.0, "error_message_eval_reason": "The error description provided by the LLM ('ValueError: Unknown label type: 'continuous'') is completely irrelevant to the ground truth error message ('Reshape your data either using array.reshape(-1, 1) if your data has a single feature or array.reshape(1, -1) if it contains a single sample.'). The ground truth error pertains to reshaping the data, while the LLM's error is about label types."}, {"cause_line_score": 1, "effect_line_score": 1, "error_type_score": 1, "error_message_score": 0.75, "error_message_eval_reason": "The error message 'invalid literal for int() with base 10' captures the essence of the error but lacks the specific detail provided in the Ground Truth ('22.0')."}, {"cause_line_score": 0, "effect_line_score": 1, "error_type_score": 1, "error_message_score": 0.75, "error_message_eval_reason": "The error description provided by the LLM Output is mostly correct but lacks minor details. It mentions 'continuous' which matches the keyword in the GT, but does not include the additional context about fitting a classifier with continuous values provided in the GT."}, {"cause_line_score": 1, "effect_line_score": 1, "error_type_score": 0, "error_message_score": 0.5, "error_message_eval_reason": "The LLM correctly identifies the cause and effect lines, matching them exactly with the Ground Truth. However, the error type related to the length mismatch in keys and values during assignment differs from the GT. The error message does hint at inconsistent sample numbers but does not accurately represent the 'equal len keys and value' issue, making it only partially correct."}, {"cause_line_score": 1, "effect_line_score": 0, "error_type_score": 1, "error_message_score": 0.75, "error_message_eval_reason": "The error message in the LLM output ('Cannot set a DataFrame with multiple values to a non-integer index') is slightly different in wording but essentially captures the same issue described in the Ground Truth ('Must have equal len keys and value when setting with an iterable'). Both indicate a mismatch between the number of keys and the iterable values, making the LLM output mostly correct but lacking the exact phrasing."}, {"cause_line_score": 0, "effect_line_score": 0, "error_type_score": 0, "error_message_score": 0.0, "error_message_eval_reason": "The LLM Output does not match the Ground Truth in any of the dimensions. The cause line, effect line, and error message are completely different from the Ground Truth. The Ground Truth indicates a KeyError due to attempting to drop a non-existent column in a dataframe, while the LLM Output describes an error related to using KNeighborsClassifier which expects discrete labels and was given continuous data. Therefore, none of the error descriptions are related to the Ground Truth context."}, {"cause_line_score": 0, "effect_line_score": 0, "error_type_score": 0, "error_message_score": 0.0, "error_message_eval_reason": "The error message in the LLM output ('KeyError: 'Child'') is completely different and unrelated to the ground truth error message ('ValueError: shape mismatch...')."}, {"cause_line_score": 1, "effect_line_score": 1, "error_type_score": 0, "error_message_score": 0.0, "error_message_eval_reason": "The error message 'TypeError: unhashable type: 'list'' provided by the LLM is completely different and unrelated to the ground truth error message 'ValueError: shape mismatch: objects cannot be broadcast to a single shape. Mismatch is between arg 0 with shape (4, 2) and arg 1 with shape (4,).'"}, {"cause_line_score": 0, "effect_line_score": 1, "error_type_score": 0, "error_message_score": 0.25, "error_message_eval_reason": "The error description in the LLM output is loosely related to the GT. The GT indicates a length mismatch between the values and the index, while the LLM output mentions inconsistent numbers of samples between input variables. Although both relate to size mismatches, they differ in their specific circumstances and details."}]}
{"id": 102, "eval_result": [{"cause_line_score": 1, "effect_line_score": 1, "error_type_score": 1, "error_message_score": 1.0, "error_message_eval_reason": "The error message 'KeyError: 'Parch'' exactly matches the Ground Truth. Both identify that the key 'Parch' was not found in the dataframe, hence it's entirely correct."}]}
{"id": 103, "eval_result": [{"cause_line_score": 0, "effect_line_score": 0, "error_type_score": 0, "error_message_score": 0.0, "error_message_eval_reason": "The error description 'ValueError: Input contains NaN, infinity or a value too large for dtype('float64').' is completely irrelevant or incorrect compared to the Ground Truth error description 'KeyError: 'sex''."}, {"cause_line_score": 0, "effect_line_score": 0, "error_type_score": 0, "error_message_score": 0.0, "error_message_eval_reason": "The error description 'ValueError: Input contains NaN, infinity or a value too large for dtype('float64').' is completely irrelevant or incorrect compared to the Ground Truth 'KeyError: 'sex''."}, {"cause_line_score": 0, "effect_line_score": 0, "error_type_score": 0, "error_message_score": 0.0, "error_message_eval_reason": "The error description 'Input contains NaN, infinity or a value too large for dtype('float64')' is completely irrelevant because the ground truth error message is 'KeyError: 'sex'' which indicates a missing key in the DataFrame, not an issue with NaN values or numerical limits."}, {"cause_line_score": 0, "effect_line_score": 0, "error_type_score": 0, "error_message_score": 0.0, "error_message_eval_reason": "The LLM's output does not match the ground truth in cause line, effect line, or error message. The ground truth indicates a KeyError related to a missing 'sex' key in a dataframe, but the LLM identifies an incorrect output format error without relating to the KeyError issue. Therefore, the error message is completely incorrect, justifying a score of 0.0."}]}
{"id": 104, "eval_result": [{"cause_line_score": 0, "effect_line_score": 0, "error_type_score": 0, "error_message_score": 0.0, "error_message_eval_reason": "The cause line, effect line, and error type in the LLM output are completely different from those provided in the Ground Truth. The Ground Truth error is related to a KeyError for the 'Rings' column, while the LLM output describes a length mismatch error. Therefore, all error descriptions are completely irrelevant to the Ground Truth."}, {"cause_line_score": 1, "effect_line_score": 1, "error_type_score": 0, "error_message_score": 0.0, "error_message_eval_reason": "The error message in the LLM output mentions a ValueError due to inconsistent numbers of samples, which is unrelated to the GT error regarding NaN values. Therefore, the error description is completely irrelevant or incorrect."}, {"cause_line_score": 0, "effect_line_score": 0, "error_type_score": 0, "error_message_score": 0.0, "error_message_eval_reason": "The error message provided by the LLM Output ('Input contains NaN, infinity or a value too large for dtype('float64')') is completely irrelevant to the Ground Truth error message ('Length mismatch: Expected axis has 8 elements, new values have 9 elements'). Therefore, a score of 0.0 is justified."}, {"cause_line_score": 1, "effect_line_score": 0, "error_type_score": 1, "error_message_score": 0.75, "error_message_eval_reason": "The error type 'ValueError' matches exactly between the Ground Truth and LLM Output. However, while both error messages refer to a mismatch in shape or length, the GT provides a specific mismatch in column length (8 elements expected vs. 9 elements provided), whereas the LLM Output describes a shape mismatch in a more generalized fashion (shape (n, m+1) vs. (n, m)). The main detail about the cause of the error is present in both descriptions."}, {"cause_line_score": 0, "effect_line_score": 0, "error_type_score": 0, "error_message_score": 0.0, "error_message_eval_reason": "The error description in the LLM Output ('ValueError: setting an array element with a sequence.') is completely different from the error description in the Ground Truth ('TypeError: LinearRegression.__init__() got an unexpected keyword argument 'normalize''). Therefore, it is completely irrelevant or incorrect."}, {"cause_line_score": 1, "effect_line_score": 1, "error_type_score": 0, "error_message_score": 0.5, "error_message_eval_reason": "The LLM's error message indicates a logical error where the model is trained on the test set and evaluated on the training set. While this is a logical issue, it does not address the actual error, which is the ValueError raised due to inconsistent numbers of samples between X_test and y_train."}, {"cause_line_score": 1, "effect_line_score": 1, "error_type_score": 0, "error_message_score": 0.0, "error_message_eval_reason": "The LLM identified the correct cause and effect lines. However, the identified error type (predictions on training instead of test set) does not match the ground truth error type (inconsistent number of samples). Therefore, the error message is completely incorrect and scores a 0.0."}, {"cause_line_score": 1, "effect_line_score": 1, "error_type_score": 0, "error_message_score": 0.5, "error_message_eval_reason": "The LLM provided an explanation that the RMSE calculation used the training set instead of the test set, which does not align with the actual error of inconsistent numbers of samples. However, it correctly identified an issue in the code relating to how RMSE was computed, though it missed the specific detail of the sample size mismatch."}, {"cause_line_score": 0, "effect_line_score": 0, "error_type_score": 0, "error_message_score": 0.0, "error_message_eval_reason": "The LLM Output identified a completely different error than the Ground Truth. The error types and their descriptions do not match at all. The Ground Truth error is related to an incorrect argument passed to LinearRegression's constructor, while the LLM Output describes a concatenation error with pandas. The provided error message in the LLM Output does not align with the error type from the Ground Truth."}, {"cause_line_score": 1, "effect_line_score": 1, "error_type_score": 0, "error_message_score": 0.25, "error_message_eval_reason": "The LLM Output is loosely connected to the GT by mentioning a potential error in model training. However, it fails to capture the specific ValueError concerning inconsistent sample sizes provided in the GT. Thus, it misses the key detail."}, {"cause_line_score": 0, "effect_line_score": 0, "error_type_score": 0, "error_message_score": 0.0, "error_message_eval_reason": "The LLM's error message points to a mismatch in input features count, but the GT error is about inconsistent numbers of samples. The two errors are completely different in nature. Therefore, the LLM description is completely irrelevant or incorrect."}, {"cause_line_score": 1, "effect_line_score": 1, "error_type_score": 0, "error_message_score": 0.25, "error_message_eval_reason": "The LLM Output mentioned an incorrect evaluation of the model's performance due to using the training set, which is loosely related. However, the primary error is due to inconsistent sample sizes between 'y_train' and 'y_pred_volume', which is not addressed in the LLM's explanation."}, {"cause_line_score": 0, "effect_line_score": 0, "error_type_score": 1, "error_message_score": 1.0, "error_message_eval_reason": "The error message 'KeyError' in the LLM output exactly matches the error message in the Ground Truth, as both indicate a missing key in the dataset."}, {"cause_line_score": 0, "effect_line_score": 0, "error_type_score": 0, "error_message_score": 0.0, "error_message_eval_reason": "The error message described by the LLM (KeyError: 'Weight') does not match the Ground Truth error message (TypeError: Could not convert [...] to numeric). There is no partial correctness as the identified error type and cause are completely different from the one given in the Ground Truth."}]}
{"id": 151, "eval_result": [{"cause_line_score": 0, "effect_line_score": 0, "error_type_score": 0, "error_message_score": 0.0, "error_message_eval_reason": "The LLM's output does not match the Ground Truth at all. The Ground Truth specifies that the cause and effect error is on the line that reads a CSV file, leading to a FileNotFoundError. The LLM's output, however, speaks about encoding columns and their usage, which is unrelated to the actual error. Hence, all scores are 0."}, {"cause_line_score": 0, "effect_line_score": 0, "error_type_score": 0, "error_message_score": 0.0, "error_message_eval_reason": "The error description in the LLM Output ('KeyError: 'Geography'') does not match the Ground Truth ('AttributeError: 'NoneType' object has no attribute 'drop''). These are completely different errors."}, {"cause_line_score": 0, "effect_line_score": 0, "error_type_score": 0, "error_message_score": 0.0, "error_message_eval_reason": "The LLM output's error message 'KeyError: 'Region'' does not match the ground truth error message 'AttributeError: 'NoneType' object has no attribute 'drop''. The errors are completely different, making the LLM's error message irrelevant to the ground truth error."}]}
{"id": 152, "eval_result": [{"cause_line_score": 0, "effect_line_score": 0, "error_type_score": 0, "error_message_score": 0.0, "error_message_eval_reason": "The LLM's error message 'KeyError: 'Final Worth (USD)'' is completely unrelated to the Ground Truth error message 'urllib.error.HTTPError: HTTP Error 404: Not Found'. The LLM's error description references a missing key in a DataFrame, whereas the Ground Truth error is about a 404 HTTP error when trying to read a CSV from a URL."}, {"cause_line_score": 0, "effect_line_score": 0, "error_type_score": 0, "error_message_score": 0.0, "error_message_eval_reason": "The LLM Output's cause and effect lines do not match the Ground Truth. The LLM identified a different line in the code as the source and effect of the error, which does not correspond to the actual cause of the error provided in the Ground Truth. Furthermore, the error message generated by the LLM describes a completely different error (ValueError related to bin labels) compared to the FileNotFoundError in the Ground Truth. Hence, the error message is irrelevant and completely incorrect."}, {"cause_line_score": 0, "effect_line_score": 0, "error_type_score": 0, "error_message_score": 0.0, "error_message_eval_reason": "The error message provided by the LLM Output ('ValueError: Unknown label type: 'unknown'') is completely different from the Ground Truth error message ('FileNotFoundError: [Errno 2] No such file or directory: 'billionaire_data.csv''). The causes and effects of errors in the LLM Output also do not match with the Ground Truth, hence a score of 0 is given in all dimensions."}, {"cause_line_score": 0, "effect_line_score": 0, "error_type_score": 0, "error_message_score": 0.0, "error_message_eval_reason": "The error message described by the LLM Output ('invalid literal for int() with base 10: 'non-numeric-value'') is completely irrelevant to the Ground Truth error message ('FileNotFoundError: [Errno 2] No such file or directory: 'billionaires.csv''). The LLM Output addresses a different type of error (TypeError vs. FileNotFoundError) and unrelated cause/effect lines, making the entire analysis incorrect."}, {"cause_line_score": 0, "effect_line_score": 0, "error_type_score": 0, "error_message_score": 0.0, "error_message_eval_reason": "The LLM Output provides an entirely different error (ValueError) and a different code line (sns.barplot) compared to the Ground Truth (FileNotFoundError on pd.read_csv). The two don't match at all, thus receiving the lowest scores across all metrics."}]}
{"id": 153, "eval_result": [{"cause_line_score": 0, "effect_line_score": 0, "error_type_score": 0, "error_message_score": 0.0, "error_message_eval_reason": "The error message 'ValueError: The truth value of a Series is ambiguous. Use a.empty, a.bool(), a.item(), a.any() or a.all().' is completely different from 'TypeError: 'NoneType' object is not subscriptable'. The error type and description do not match at all."}, {"cause_line_score": 0, "effect_line_score": 0, "error_type_score": 0, "error_message_score": 0.0, "error_message_eval_reason": "The error description provided by the LLM ('ValueError: could not convert string to float: 'Yes'') is completely different from the Ground Truth ('FileNotFoundError: [Errno 2] No such file or directory: 'data.csv''). These two errors are unrelated."}, {"cause_line_score": 0, "effect_line_score": 0, "error_type_score": 0, "error_message_score": 0.0, "error_message_eval_reason": "The error message 'ValueError: x and y must be 1D arrays of the same length.' in the LLM output is completely different from 'TypeError: 'NoneType' object is not subscriptable' in the ground truth, leading to a completely incorrect analysis."}]}
{"id": 154, "eval_result": [{"cause_line_score": 0, "effect_line_score": 0, "error_type_score": 0, "error_message_score": 0.0, "error_message_eval_reason": "The LLM output provided a completely different error message ('TypeError: 'int' object is not subscriptable') compared to the ground truth ('AttributeError: 'NoneType' object has no attribute 'drop_duplicates'). The cause line and effect line provided by the LLM are also different from those in the ground truth."}, {"cause_line_score": 0, "effect_line_score": 0, "error_type_score": 0, "error_message_score": 0.0, "error_message_eval_reason": "The error description in the LLM Output is 'ValueError: Cannot convert non-finite values (NA or inf) to integer', which is completely different from the GT error 'AttributeError: 'NoneType' object has no attribute 'drop_duplicates''. The GT error pertains to an attribute error related to a 'NoneType' object, while the LLM error pertains to a ValueError related to non-finite values."}, {"cause_line_score": 0, "effect_line_score": 0, "error_type_score": 0, "error_message_score": 0.0, "error_message_eval_reason": "The error message provided by the LLM, 'Cannot convert non-finite values (NA or inf) to integer,' is completely different from the ground truth error, 'AttributeError: 'NoneType' object has no attribute 'drop_duplicates.'' Therefore, the descriptions are irrelevant to each other."}, {"cause_line_score": 0, "effect_line_score": 0, "error_type_score": 0, "error_message_score": 0.0, "error_message_eval_reason": "The error message `AttributeError: 'NoneType' object has no attribute 'drop_duplicates'` from the Ground Truth does not align with the LLM output message of `AttributeError: 'Categorical' object has no attribute 'mean'`. Both the object types (`NoneType` vs `Categorical`) and the specific attributes (`drop_duplicates` vs `mean`) referenced in the error messages are different. Therefore, the error description is completely irrelevant or incorrect."}]}
{"id": 155, "eval_result": [{"cause_line_score": 0, "effect_line_score": 0, "error_type_score": 0, "error_message_score": 0.0, "error_message_eval_reason": "The LLM output describes an incorrect condition for identifying outliers in a dataset, while the ground truth indicates a FileNotFoundError due to missing 'salaries.csv' file. The errors are completely different and unrelated, hence the cause line, effect line, error type, and error message scores are all 0."}]}
